Workbook

Sheet Duke Rankings (no proof)
A1: che | B1: Ion ID | C1: Overall Index | D1: Duke 1 | E1: Duke 2 | F1: Duke 3 | G1: Duke 4 | H1: Proof
A2: =ROW()-1 -> 1 | B2: 2026rwang | C2: =0.35*LARGE(D2:G2,1)+0.35*LARGE(D2:G2,2)+0.2*LARGE(D2:G2,3) -> 4155.1111 | D2: =IFERROR(VLOOKUP(B2, 'Duke 1'!A$3:$B$85,2, 0), 0) -> 3157.8947 | E2: =IFERROR(VLOOKUP(B2, 'Duke 2'!A$3:$B$522,2, 0), 0) -> 6000 | F2: =IFERROR(VLOOKUP(B2, 'Duke 3'!A$3:$B1000,2, 0), 0) -> 3555.5556 | G2: =IFERROR(VLOOKUP(B2, 'Duke 4'!A$3:$B1000,2, 0), 0) -> 3840 | H2: 4341
A3: =ROW()-1 -> 2 | B3: 2028syan | C3: =0.35*LARGE(D3:G3,1)+0.35*LARGE(D3:G3,2)+0.2*LARGE(D3:G3,3) -> 2353.8713 | D3: =IFERROR(VLOOKUP(B3, 'Duke 1'!A$3:$B$85,2, 0), 0) -> 3789.4737 | E3: =IFERROR(VLOOKUP(B3, 'Duke 2'!A$3:$B$522,2, 0), 0) -> 1500 | F3: =IFERROR(VLOOKUP(B3, 'Duke 3'!A$3:$B1000,2, 0), 0) -> 1777.7778 | G3: =IFERROR(VLOOKUP(B3, 'Duke 4'!A$3:$B1000,2, 0), 0) -> 1920 | H3: =IFERROR(VLOOKUP(B3, Proof!A$2:$B1000,2, 0), 0) -> 2472.7273
A4: =ROW()-1 -> 3 | B4: 2026mzhao | C4: =0.35*LARGE(D4:G4,1)+0.35*LARGE(D4:G4,2)+0.2*LARGE(D4:G4,3) -> 2266.2222 | D4: =IFERROR(VLOOKUP(B4, 'Duke 1'!A$3:$B$85,2, 0), 0) -> 1263.1579 | E4: =IFERROR(VLOOKUP(B4, 'Duke 2'!A$3:$B$522,2, 0), 0) -> 1500 | F4: =IFERROR(VLOOKUP(B4, 'Duke 3'!A$3:$B1000,2, 0), 0) -> 1777.7778 | G4: =IFERROR(VLOOKUP(B4, 'Duke 4'!A$3:$B1000,2, 0), 0) -> 3840 | H4: =IFERROR(VLOOKUP(B4, Proof!A$2:$B1000,2, 0), 0) -> 0
A5: =ROW()-1 -> 4 | B5: 2027pdu | C5: =0.35*LARGE(D5:G5,1)+0.35*LARGE(D5:G5,2)+0.2*LARGE(D5:G5,3) -> 2132.8187 | D5: =IFERROR(VLOOKUP(B5, 'Duke 1'!A$3:$B$85,2, 0), 0) -> 3157.8947 | E5: =IFERROR(VLOOKUP(B5, 'Duke 2'!A$3:$B$522,2, 0), 0) -> 1500 | F5: =IFERROR(VLOOKUP(B5, 'Duke 3'!A$3:$B1000,2, 0), 0) -> 1777.7778 | G5: =IFERROR(VLOOKUP(B5, 'Duke 4'!A$3:$B1000,2, 0), 0) -> 1920 | H5: =IFERROR(VLOOKUP(B5, Proof!A$2:$B1000,2, 0), 0) -> 1309.0909
A6: =ROW()-1 -> 5 | B6: 2027smahmud | C6: =0.35*LARGE(D6:G6,1)+0.35*LARGE(D6:G6,2)+0.2*LARGE(D6:G6,3) -> 1905.3333 | D6: =IFERROR(VLOOKUP(B6, 'Duke 1'!A$3:$B$85,2, 0), 0) -> 0 | E6: =IFERROR(VLOOKUP(B6, 'Duke 2'!A$3:$B$522,2, 0), 0) -> 1500 | F6: =IFERROR(VLOOKUP(B6, 'Duke 3'!A$3:$B1000,2, 0), 0) -> 2666.6667 | G6: =IFERROR(VLOOKUP(B6, 'Duke 4'!A$3:$B1000,2, 0), 0) -> 1920
A7: =ROW()-1 -> 6 | B7: 2026jma | C7: =0.35*LARGE(D7:G7,1)+0.35*LARGE(D7:G7,2)+0.2*LARGE(D7:G7,3) -> 1806.4327 | D7: =IFERROR(VLOOKUP(B7, 'Duke 1'!A$3:$B$85,2, 0), 0) -> 2526.3158 | E7: =IFERROR(VLOOKUP(B7, 'Duke 2'!A$3:$B$522,2, 0), 0) -> 1500 | F7: =IFERROR(VLOOKUP(B7, 'Duke 3'!A$3:$B1000,2, 0), 0) -> 1777.7778 | G7: =IFERROR(VLOOKUP(B7, 'Duke 4'!A$3:$B1000,2, 0), 0) -> 960 | H7: =IFERROR(VLOOKUP(B7, Proof!A$2:$B1000,2, 0), 0) -> 2036.3636
A8: =ROW()-1 -> 7 | B8: 2028szhang | C8: =0.35*LARGE(D8:G8,1)+0.35*LARGE(D8:G8,2)+0.2*LARGE(D8:G8,3) -> 1710.7778 | D8: =IFERROR(VLOOKUP(B8, 'Duke 1'!A$3:$B$85,2, 0), 0) -> 631.57895 | E8: =IFERROR(VLOOKUP(B8, 'Duke 2'!A$3:$B$522,2, 0), 0) -> 1500 | F8: =IFERROR(VLOOKUP(B8, 'Duke 3'!A$3:$B1000,2, 0), 0) -> 888.88889 | G8: =IFERROR(VLOOKUP(B8, 'Duke 4'!A$3:$B1000,2, 0), 0) -> 2880 | H8: =IFERROR(VLOOKUP(B8, Proof!A$2:$B1000,2, 0), 0) -> 1018.1818
A9: =ROW()-1 -> 8 | B9: 2027esombhat | C9: =0.35*LARGE(D9:G9,1)+0.35*LARGE(D9:G9,2)+0.2*LARGE(D9:G9,3) -> 1601.2105 | D9: =IFERROR(VLOOKUP(B9, 'Duke 1'!A$3:$B$85,2, 0), 0) -> 2526.3158 | E9: =IFERROR(VLOOKUP(B9, 'Duke 2'!A$3:$B$522,2, 0), 0) -> 1500 | F9: =IFERROR(VLOOKUP(B9, 'Duke 3'!A$3:$B1000,2, 0), 0) -> 888.88889 | G9: =IFERROR(VLOOKUP(B9, 'Duke 4'!A$3:$B1000,2, 0), 0) -> 960 | H9: =IFERROR(VLOOKUP(B9, Proof!A$2:$B1000,2, 0), 0) -> 1890.9091
A10: =ROW()-1 -> 9 | B10: 2028mlin | C10: =0.35*LARGE(D10:G10,1)+0.35*LARGE(D10:G10,2)+0.2*LARGE(D10:G10,3) -> 1594.2222 | D10: =IFERROR(VLOOKUP(B10, 'Duke 1'!A$3:$B$85,2, 0), 0) -> 0 | E10: =IFERROR(VLOOKUP(B10, 'Duke 2'!A$3:$B$522,2, 0), 0) -> 1500 | F10: =IFERROR(VLOOKUP(B10, 'Duke 3'!A$3:$B1000,2, 0), 0) -> 1777.7778 | G10: =IFERROR(VLOOKUP(B10, 'Duke 4'!A$3:$B1000,2, 0), 0) -> 1920
A11: =ROW()-1 -> 10 | B11: 2027vcao | C11: =0.35*LARGE(D11:G11,1)+0.35*LARGE(D11:G11,2)+0.2*LARGE(D11:G11,3) -> 1477.3801 | D11: =IFERROR(VLOOKUP(B11, 'Duke 1'!A$3:$B$85,2, 0), 0) -> 1894.7368 | E11: =IFERROR(VLOOKUP(B11, 'Duke 2'!A$3:$B$522,2, 0), 0) -> 0 | F11: =IFERROR(VLOOKUP(B11, 'Duke 3'!A$3:$B1000,2, 0), 0) -> 1777.7778 | G11: =IFERROR(VLOOKUP(B11, 'Duke 4'!A$3:$B1000,2, 0), 0) -> 960
A12: =ROW()-1 -> 11 | B12: 2027ahao | C12: =0.35*LARGE(D12:G12,1)+0.35*LARGE(D12:G12,2)+0.2*LARGE(D12:G12,3) -> 1399.8538 | D12: =IFERROR(VLOOKUP(B12, 'Duke 1'!A$3:$B$85,2, 0), 0) -> 1263.1579 | E12: =IFERROR(VLOOKUP(B12, 'Duke 2'!A$3:$B$522,2, 0), 0) -> 1500 | F12: =IFERROR(VLOOKUP(B12, 'Duke 3'!A$3:$B1000,2, 0), 0) -> 1777.7778 | G12: =IFERROR(VLOOKUP(B12, 'Duke 4'!A$3:$B1000,2, 0), 0) -> 960 | H12: =IFERROR(VLOOKUP(B12, Proof!A$2:$B1000,2, 0), 0) -> 1745.4545
A13: =ROW()-1 -> 12 | B13: 2027itennyso | C13: =0.35*LARGE(D13:G13,1)+0.35*LARGE(D13:G13,2)+0.2*LARGE(D13:G13,3) -> 1399.8538 | D13: =IFERROR(VLOOKUP(B13, 'Duke 1'!A$3:$B$85,2, 0), 0) -> 1263.1579 | E13: =IFERROR(VLOOKUP(B13, 'Duke 2'!A$3:$B$522,2, 0), 0) -> 1500 | F13: =IFERROR(VLOOKUP(B13, 'Duke 3'!A$3:$B1000,2, 0), 0) -> 1777.7778 | G13: =IFERROR(VLOOKUP(B13, 'Duke 4'!A$3:$B1000,2, 0), 0) -> 960
A14: =ROW()-1 -> 13 | B14: 2029adu | C14: =0.35*LARGE(D14:G14,1)+0.35*LARGE(D14:G14,2)+0.2*LARGE(D14:G14,3) -> 1339.2222 | D14: =IFERROR(VLOOKUP(B14, 'Duke 1'!A$3:$B$85,2, 0), 0) -> 631.57895 | E14: =IFERROR(VLOOKUP(B14, 'Duke 2'!A$3:$B$522,2, 0), 0) -> 1500 | F14: =IFERROR(VLOOKUP(B14, 'Duke 3'!A$3:$B1000,2, 0), 0) -> 1777.7778 | G14: =IFERROR(VLOOKUP(B14, 'Duke 4'!A$3:$B1000,2, 0), 0) -> 960 | H14: =IFERROR(VLOOKUP(B14, Proof!A$2:$B1000,2, 0), 0) -> 145.45455
A15: =ROW()-1 -> 14 | B15: 2026rsingh2 | C15: =0.35*LARGE(D15:G15,1)+0.35*LARGE(D15:G15,2)+0.2*LARGE(D15:G15,3) -> 1339.2222 | D15: =IFERROR(VLOOKUP(B15, 'Duke 1'!A$3:$B$85,2, 0), 0) -> 0 | E15: =IFERROR(VLOOKUP(B15, 'Duke 2'!A$3:$B$522,2, 0), 0) -> 1500 | F15: =IFERROR(VLOOKUP(B15, 'Duke 3'!A$3:$B1000,2, 0), 0) -> 1777.7778 | G15: =IFERROR(VLOOKUP(B15, 'Duke 4'!A$3:$B1000,2, 0), 0) -> 960
A16: =ROW()-1 -> 15 | B16: 2029jdu | C16: =0.35*LARGE(D16:G16,1)+0.35*LARGE(D16:G16,2)+0.2*LARGE(D16:G16,3) -> 1339.2222 | D16: =IFERROR(VLOOKUP(B16, 'Duke 1'!A$3:$B$85,2, 0), 0) -> 0 | E16: =IFERROR(VLOOKUP(B16, 'Duke 2'!A$3:$B$522,2, 0), 0) -> 1500 | F16: =IFERROR(VLOOKUP(B16, 'Duke 3'!A$3:$B1000,2, 0), 0) -> 1777.7778 | G16: =IFERROR(VLOOKUP(B16, 'Duke 4'!A$3:$B1000,2, 0), 0) -> 960
A17: =ROW()-1 -> 16 | B17: 2027achu | C17: =0.35*LARGE(D17:G17,1)+0.35*LARGE(D17:G17,2)+0.2*LARGE(D17:G17,3) -> 1323.3158 | D17: =IFERROR(VLOOKUP(B17, 'Duke 1'!A$3:$B$85,2, 0), 0) -> 631.57895 | E17: =IFERROR(VLOOKUP(B17, 'Duke 2'!A$3:$B$522,2, 0), 0) -> 1500 | F17: =IFERROR(VLOOKUP(B17, 'Duke 3'!A$3:$B1000,2, 0), 0) -> 0 | G17: =IFERROR(VLOOKUP(B17, 'Duke 4'!A$3:$B1000,2, 0), 0) -> 1920 | H17: =IFERROR(VLOOKUP(B17, Proof!A$2:$B1000,2, 0), 0) -> 1163.6364
A18: =ROW()-1 -> 17 | B18: 2027eguo | C18: =0.35*LARGE(D18:G18,1)+0.35*LARGE(D18:G18,2)+0.2*LARGE(D18:G18,3) -> 1273.538 | D18: =IFERROR(VLOOKUP(B18, 'Duke 1'!A$3:$B$85,2, 0), 0) -> 631.57895 | E18: =IFERROR(VLOOKUP(B18, 'Duke 2'!A$3:$B$522,2, 0), 0) -> 1500 | F18: =IFERROR(VLOOKUP(B18, 'Duke 3'!A$3:$B1000,2, 0), 0) -> 1777.7778 | G18: =IFERROR(VLOOKUP(B18, 'Duke 4'!A$3:$B1000,2, 0), 0) -> 0 | H18: =IFERROR(VLOOKUP(B18, Proof!A$2:$B1000,2, 0), 0) -> 1890.9091
A19: =ROW()-1 -> 18 | B19: 2029nmaloney | C19: =0.35*LARGE(D19:G19,1)+0.35*LARGE(D19:G19,2)+0.2*LARGE(D19:G19,3) -> 1271.0526 | D19: =IFERROR(VLOOKUP(B19, 'Duke 1'!A$3:$B$85,2, 0), 0) -> 631.57895 | E19: =IFERROR(VLOOKUP(B19, 'Duke 2'!A$3:$B$522,2, 0), 0) -> 3000 | F19: =IFERROR(VLOOKUP(B19, 'Duke 3'!A$3:$B1000,2, 0), 0) -> 0 | G19: =IFERROR(VLOOKUP(B19, 'Duke 4'!A$3:$B1000,2, 0), 0) -> 0 | H19: =IFERROR(VLOOKUP(B19, Proof!A$2:$B1000,2, 0), 0) -> 0
A20: =ROW()-1 -> 19 | B20: 2029sbi | C20: =0.35*LARGE(D20:G20,1)+0.35*LARGE(D20:G20,2)+0.2*LARGE(D20:G20,3) -> 1159.1053 | D20: =IFERROR(VLOOKUP(B20, 'Duke 1'!A$3:$B$85,2, 0), 0) -> 1263.1579 | E20: =IFERROR(VLOOKUP(B20, 'Duke 2'!A$3:$B$522,2, 0), 0) -> 1500 | F20: =IFERROR(VLOOKUP(B20, 'Duke 3'!A$3:$B1000,2, 0), 0) -> 888.88889 | G20: =IFERROR(VLOOKUP(B20, 'Duke 4'!A$3:$B1000,2, 0), 0) -> 960 | H20: =IFERROR(VLOOKUP(B20, Proof!A$2:$B1000,2, 0), 0) -> 0
A21: =ROW()-1 -> 20 | B21: 2028ktabakov | C21: =0.35*LARGE(D21:G21,1)+0.35*LARGE(D21:G21,2)+0.2*LARGE(D21:G21,3) -> 1147.2222 | D21: =IFERROR(VLOOKUP(B21, 'Duke 1'!A$3:$B$85,2, 0), 0) -> 0 | E21: =IFERROR(VLOOKUP(B21, 'Duke 2'!A$3:$B$522,2, 0), 0) -> 1500 | F21: =IFERROR(VLOOKUP(B21, 'Duke 3'!A$3:$B1000,2, 0), 0) -> 1777.7778 | G21: =IFERROR(VLOOKUP(B21, 'Duke 4'!A$3:$B1000,2, 0), 0) -> 0
A22: =ROW()-1 -> 21 | B22: 2027eshan | C22: =0.35*LARGE(D22:G22,1)+0.35*LARGE(D22:G22,2)+0.2*LARGE(D22:G22,3) -> 1144.883 | D22: =IFERROR(VLOOKUP(B22, 'Duke 1'!A$3:$B$85,2, 0), 0) -> 1263.1579 | E22: =IFERROR(VLOOKUP(B22, 'Duke 2'!A$3:$B$522,2, 0), 0) -> 1500 | F22: =IFERROR(VLOOKUP(B22, 'Duke 3'!A$3:$B1000,2, 0), 0) -> 888.88889 | G22: =IFERROR(VLOOKUP(B22, 'Duke 4'!A$3:$B1000,2, 0), 0) -> 0 | H22: =IFERROR(VLOOKUP(B22, Proof!A$2:$B1000,2, 0), 0) -> 1745.4545
A23: =ROW()-1 -> 22 | B23: 2026owu | C23: =0.35*LARGE(D23:G23,1)+0.35*LARGE(D23:G23,2)+0.2*LARGE(D23:G23,3) -> 1038.7778 | D23: =IFERROR(VLOOKUP(B23, 'Duke 1'!A$3:$B$85,2, 0), 0) -> 631.57895 | E23: =IFERROR(VLOOKUP(B23, 'Duke 2'!A$3:$B$522,2, 0), 0) -> 1500 | F23: =IFERROR(VLOOKUP(B23, 'Duke 3'!A$3:$B1000,2, 0), 0) -> 888.88889 | G23: =IFERROR(VLOOKUP(B23, 'Duke 4'!A$3:$B1000,2, 0), 0) -> 960 | H23: =IFERROR(VLOOKUP(B23, Proof!A$2:$B1000,2, 0), 0) -> 1018.1818
A24: =ROW()-1 -> 23 | B24: 2027mbu | C24: =0.35*LARGE(D24:G24,1)+0.35*LARGE(D24:G24,2)+0.2*LARGE(D24:G24,3) -> 1038.7778 | D24: =IFERROR(VLOOKUP(B24, 'Duke 1'!A$3:$B$85,2, 0), 0) -> 631.57895 | E24: =IFERROR(VLOOKUP(B24, 'Duke 2'!A$3:$B$522,2, 0), 0) -> 1500 | F24: =IFERROR(VLOOKUP(B24, 'Duke 3'!A$3:$B1000,2, 0), 0) -> 888.88889 | G24: =IFERROR(VLOOKUP(B24, 'Duke 4'!A$3:$B1000,2, 0), 0) -> 960
A25: =ROW()-1 -> 24 | B25: 2029wli | C25: =0.35*LARGE(D25:G25,1)+0.35*LARGE(D25:G25,2)+0.2*LARGE(D25:G25,3) -> 1038.7778 | D25: =IFERROR(VLOOKUP(B25, 'Duke 1'!A$3:$B$85,2, 0), 0) -> 631.57895 | E25: =IFERROR(VLOOKUP(B25, 'Duke 2'!A$3:$B$522,2, 0), 0) -> 1500 | F25: =IFERROR(VLOOKUP(B25, 'Duke 3'!A$3:$B1000,2, 0), 0) -> 888.88889 | G25: =IFERROR(VLOOKUP(B25, 'Duke 4'!A$3:$B1000,2, 0), 0) -> 960
A26: =ROW()-1 -> 25 | B26: 2028yli | C26: =0.35*LARGE(D26:G26,1)+0.35*LARGE(D26:G26,2)+0.2*LARGE(D26:G26,3) -> 1038.7778 | D26: =IFERROR(VLOOKUP(B26, 'Duke 1'!A$3:$B$85,2, 0), 0) -> 631.57895 | E26: =IFERROR(VLOOKUP(B26, 'Duke 2'!A$3:$B$522,2, 0), 0) -> 1500 | F26: =IFERROR(VLOOKUP(B26, 'Duke 3'!A$3:$B1000,2, 0), 0) -> 888.88889 | G26: =IFERROR(VLOOKUP(B26, 'Duke 4'!A$3:$B1000,2, 0), 0) -> 960 | H26: =IFERROR(VLOOKUP(B26, Proof!A$2:$B1000,2, 0), 0) -> 1163.6364
A27: =ROW()-1 -> 26 | B27: 2026cmorimot | C27: =0.35*LARGE(D27:G27,1)+0.35*LARGE(D27:G27,2)+0.2*LARGE(D27:G27,3) -> 1038.7778 | D27: =IFERROR(VLOOKUP(B27, 'Duke 1'!A$3:$B$85,2, 0), 0) -> 0 | E27: =IFERROR(VLOOKUP(B27, 'Duke 2'!A$3:$B$522,2, 0), 0) -> 1500 | F27: =IFERROR(VLOOKUP(B27, 'Duke 3'!A$3:$B1000,2, 0), 0) -> 888.88889 | G27: =IFERROR(VLOOKUP(B27, 'Duke 4'!A$3:$B1000,2, 0), 0) -> 960
A28: =ROW()-1 -> 27 | B28: 2028gkeeler | C28: =0.35*LARGE(D28:G28,1)+0.35*LARGE(D28:G28,2)+0.2*LARGE(D28:G28,3) -> 1038.7778 | D28: =IFERROR(VLOOKUP(B28, 'Duke 1'!A$3:$B$85,2, 0), 0) -> 0 | E28: =IFERROR(VLOOKUP(B28, 'Duke 2'!A$3:$B$522,2, 0), 0) -> 1500 | F28: =IFERROR(VLOOKUP(B28, 'Duke 3'!A$3:$B1000,2, 0), 0) -> 888.88889 | G28: =IFERROR(VLOOKUP(B28, 'Duke 4'!A$3:$B1000,2, 0), 0) -> 960
A29: =ROW()-1 -> 28 | B29: 2029gbatkhuu | C29: =0.35*LARGE(D29:G29,1)+0.35*LARGE(D29:G29,2)+0.2*LARGE(D29:G29,3) -> 1038.7778 | D29: =IFERROR(VLOOKUP(B29, 'Duke 1'!A$3:$B$85,2, 0), 0) -> 0 | E29: =IFERROR(VLOOKUP(B29, 'Duke 2'!A$3:$B$522,2, 0), 0) -> 1500 | F29: =IFERROR(VLOOKUP(B29, 'Duke 3'!A$3:$B1000,2, 0), 0) -> 888.88889 | G29: =IFERROR(VLOOKUP(B29, 'Duke 4'!A$3:$B1000,2, 0), 0) -> 960
A30: =ROW()-1 -> 29 | B30: 2027achakrav | C30: =0.35*LARGE(D30:G30,1)+0.35*LARGE(D30:G30,2)+0.2*LARGE(D30:G30,3) -> 1038.7778 | D30: =IFERROR(VLOOKUP(B30, 'Duke 1'!A$3:$B$85,2, 0), 0) -> 631.57895 | E30: =IFERROR(VLOOKUP(B30, 'Duke 2'!A$3:$B$522,2, 0), 0) -> 1500 | F30: =IFERROR(VLOOKUP(B30, 'Duke 3'!A$3:$B1000,2, 0), 0) -> 888.88889 | G30: =IFERROR(VLOOKUP(B30, 'Duke 4'!A$3:$B1000,2, 0), 0) -> 960
A31: =ROW()-1 -> 30 | B31: 2027eqiu | C31: =0.35*LARGE(D31:G31,1)+0.35*LARGE(D31:G31,2)+0.2*LARGE(D31:G31,3) -> 1038.7778 | D31: =IFERROR(VLOOKUP(B31, 'Duke 1'!A$3:$B$85,2, 0), 0) -> 631.57895 | E31: =IFERROR(VLOOKUP(B31, 'Duke 2'!A$3:$B$522,2, 0), 0) -> 1500 | F31: =IFERROR(VLOOKUP(B31, 'Duke 3'!A$3:$B1000,2, 0), 0) -> 888.88889 | G31: =IFERROR(VLOOKUP(B31, 'Duke 4'!A$3:$B1000,2, 0), 0) -> 960
A32: =ROW()-1 -> 31 | B32: 2027nliang | C32: =0.35*LARGE(D32:G32,1)+0.35*LARGE(D32:G32,2)+0.2*LARGE(D32:G32,3) -> 987.31579 | D32: =IFERROR(VLOOKUP(B32, 'Duke 1'!A$3:$B$85,2, 0), 0) -> 631.57895 | E32: =IFERROR(VLOOKUP(B32, 'Duke 2'!A$3:$B$522,2, 0), 0) -> 1500 | F32: =IFERROR(VLOOKUP(B32, 'Duke 3'!A$3:$B1000,2, 0), 0) -> 0 | G32: =IFERROR(VLOOKUP(B32, 'Duke 4'!A$3:$B1000,2, 0), 0) -> 960 | H32: =IFERROR(VLOOKUP(B32, Proof!A$2:$B1000,2, 0), 0) -> 0
A33: =ROW()-1 -> 32 | B33: 2027sbisht | C33: =0.35*LARGE(D33:G33,1)+0.35*LARGE(D33:G33,2)+0.2*LARGE(D33:G33,3) -> 987.31579 | D33: =IFERROR(VLOOKUP(B33, 'Duke 1'!A$3:$B$85,2, 0), 0) -> 631.57895 | E33: =IFERROR(VLOOKUP(B33, 'Duke 2'!A$3:$B$522,2, 0), 0) -> 1500 | F33: =IFERROR(VLOOKUP(B33, 'Duke 3'!A$3:$B1000,2, 0), 0) -> 0 | G33: =IFERROR(VLOOKUP(B33, 'Duke 4'!A$3:$B1000,2, 0), 0) -> 960 | H33: =IFERROR(VLOOKUP(B33, Proof!A$2:$B1000,2, 0), 0) -> 0
A34: =ROW()-1 -> 33 | B34: 2028athota | C34: =0.35*LARGE(D34:G34,1)+0.35*LARGE(D34:G34,2)+0.2*LARGE(D34:G34,3) -> 962.4269 | D34: =IFERROR(VLOOKUP(B34, 'Duke 1'!A$3:$B$85,2, 0), 0) -> 631.57895 | E34: =IFERROR(VLOOKUP(B34, 'Duke 2'!A$3:$B$522,2, 0), 0) -> 1500 | F34: =IFERROR(VLOOKUP(B34, 'Duke 3'!A$3:$B1000,2, 0), 0) -> 888.88889 | G34: =IFERROR(VLOOKUP(B34, 'Duke 4'!A$3:$B1000,2, 0), 0) -> 0 | H34: =IFERROR(VLOOKUP(B34, Proof!A$2:$B1000,2, 0), 0) -> 145.45455
A35: =ROW()-1 -> 34 | B35: 2028dhe | C35: =0.35*LARGE(D35:G35,1)+0.35*LARGE(D35:G35,2)+0.2*LARGE(D35:G35,3) -> 861 | D35: =IFERROR(VLOOKUP(B35, 'Duke 1'!A$3:$B$85,2, 0), 0) -> 0 | E35: =IFERROR(VLOOKUP(B35, 'Duke 2'!A$3:$B$522,2, 0), 0) -> 1500 | F35: =IFERROR(VLOOKUP(B35, 'Duke 3'!A$3:$B1000,2, 0), 0) -> 0 | G35: =IFERROR(VLOOKUP(B35, 'Duke 4'!A$3:$B1000,2, 0), 0) -> 960
A36: =ROW()-1 -> 35 | B36: 2028rzhao | C36: =0.35*LARGE(D36:G36,1)+0.35*LARGE(D36:G36,2)+0.2*LARGE(D36:G36,3) -> 861 | D36: =IFERROR(VLOOKUP(B36, 'Duke 1'!A$3:$B$85,2, 0), 0) -> 0 | E36: =IFERROR(VLOOKUP(B36, 'Duke 2'!A$3:$B$522,2, 0), 0) -> 1500 | F36: =IFERROR(VLOOKUP(B36, 'Duke 3'!A$3:$B1000,2, 0), 0) -> 0 | G36: =IFERROR(VLOOKUP(B36, 'Duke 4'!A$3:$B1000,2, 0), 0) -> 960
A37: =ROW()-1 -> 36 | B37: 2028dvladimi | C37: =0.35*LARGE(D37:G37,1)+0.35*LARGE(D37:G37,2)+0.2*LARGE(D37:G37,3) -> 861 | D37: =IFERROR(VLOOKUP(B37, 'Duke 1'!A$3:$B$85,2, 0), 0) -> 0 | E37: =IFERROR(VLOOKUP(B37, 'Duke 2'!A$3:$B$522,2, 0), 0) -> 1500 | F37: =IFERROR(VLOOKUP(B37, 'Duke 3'!A$3:$B1000,2, 0), 0) -> 0 | G37: =IFERROR(VLOOKUP(B37, 'Duke 4'!A$3:$B1000,2, 0), 0) -> 960
A38: =ROW()-1 -> 37 | B38: 2028sari | C38: =0.35*LARGE(D38:G38,1)+0.35*LARGE(D38:G38,2)+0.2*LARGE(D38:G38,3) -> 861 | D38: =IFERROR(VLOOKUP(B38, 'Duke 1'!A$3:$B$85,2, 0), 0) -> 0 | E38: =IFERROR(VLOOKUP(B38, 'Duke 2'!A$3:$B$522,2, 0), 0) -> 1500 | F38: =IFERROR(VLOOKUP(B38, 'Duke 3'!A$3:$B1000,2, 0), 0) -> 0 | G38: =IFERROR(VLOOKUP(B38, 'Duke 4'!A$3:$B1000,2, 0), 0) -> 960
A39: =ROW()-1 -> 38 | B39: 2029mkim1 | C39: =0.35*LARGE(D39:G39,1)+0.35*LARGE(D39:G39,2)+0.2*LARGE(D39:G39,3) -> 861 | D39: =IFERROR(VLOOKUP(B39, 'Duke 1'!A$3:$B$85,2, 0), 0) -> 0 | E39: =IFERROR(VLOOKUP(B39, 'Duke 2'!A$3:$B$522,2, 0), 0) -> 1500 | F39: =IFERROR(VLOOKUP(B39, 'Duke 3'!A$3:$B1000,2, 0), 0) -> 0 | G39: =IFERROR(VLOOKUP(B39, 'Duke 4'!A$3:$B1000,2, 0), 0) -> 960
A40: =ROW()-1 -> 39 | B40: 2029yahn | C40: =0.35*LARGE(D40:G40,1)+0.35*LARGE(D40:G40,2)+0.2*LARGE(D40:G40,3) -> 861 | D40: =IFERROR(VLOOKUP(B40, 'Duke 1'!A$3:$B$85,2, 0), 0) -> 0 | E40: =IFERROR(VLOOKUP(B40, 'Duke 2'!A$3:$B$522,2, 0), 0) -> 1500 | F40: =IFERROR(VLOOKUP(B40, 'Duke 3'!A$3:$B1000,2, 0), 0) -> 0 | G40: =IFERROR(VLOOKUP(B40, 'Duke 4'!A$3:$B1000,2, 0), 0) -> 960
...

Sheet Duke Rankings (proof)
A1: che | B1: Ion ID | C1: Overall Index | D1: Duke 1 | E1: Duke 2 | F1: Duke 3 | G1: Duke 4 | H1: Proof | K1: Ion ID | L1: Overall Index | M1: Duke 1 | N1: Duke 2 | O1: Duke 3 | P1: Duke 4 | Q1: Proof
A2: =ROW()-1 -> 1 | B2: 2026rwang | C2: =0.35*LARGE(D2:G2,1)+0.35*LARGE(D2:G2,2)+0.2*LARGE(D2:G2,3)+0.1*H2 -> 4589.2111 | D2: =IFERROR(VLOOKUP(B2, 'Duke 1'!A$3:$B$85,2, 0), 0) -> 3157.8947 | E2: =IFERROR(VLOOKUP(B2, 'Duke 2'!A$3:$B$522,2, 0), 0) -> 6000 | F2: =IFERROR(VLOOKUP(B2, 'Duke 3'!A$3:$B998,2, 0), 0) -> 3555.5556 | G2: =IFERROR(VLOOKUP(B2, 'Duke 4'!A$3:$B998,2, 0), 0) -> 3840 | H2: =IFERROR(VLOOKUP(B2, Proof!A$2:$B998,2, 0), 0) -> 4341 | J2: experimental 20% proof weighting | K2: 2026rwang | L2: =0.3*LARGE(M2:P2,1)+0.3*LARGE(M2:P2,2)+0.2*LARGE(M2:P2,3)+0.2*Q2 -> 4531.3111 | M2: =IFERROR(VLOOKUP(K2, 'Duke 1'!$A$3:$B998,2, 0), 0) -> 3157.8947 | N2: =IFERROR(VLOOKUP(K2, 'Duke 2'!$A$3:$B998,2, 0), 0) -> 6000 | O2: =IFERROR(VLOOKUP(K2, 'Duke 3'!$A$3:$B998,2, 0), 0) -> 3555.5556 | P2: =IFERROR(VLOOKUP(K2, 'Duke 4'!$A$3:$B998,2, 0), 0) -> 3840 | Q2: =IFERROR(VLOOKUP(K2, Proof!$A$3:B998,2, 0), 0) -> 4341
A3: =ROW()-1 -> 2 | B3: 2028syan | C3: =0.35*LARGE(D3:G3,1)+0.35*LARGE(D3:G3,2)+0.2*LARGE(D3:G3,3)+0.1*H3 -> 2601.1441 | D3: =IFERROR(VLOOKUP(B3, 'Duke 1'!A$3:$B$85,2, 0), 0) -> 3789.4737 | E3: =IFERROR(VLOOKUP(B3, 'Duke 2'!A$3:$B$522,2, 0), 0) -> 1500 | F3: =IFERROR(VLOOKUP(B3, 'Duke 3'!A$3:$B998,2, 0), 0) -> 1777.7778 | G3: =IFERROR(VLOOKUP(B3, 'Duke 4'!A$3:$B998,2, 0), 0) -> 1920 | H3: =IFERROR(VLOOKUP(B3, Proof!A$2:$B998,2, 0), 0) -> 2472.7273 | K3: 2028syan | L3: =0.3*LARGE(M3:P3,1)+0.3*LARGE(M3:P3,2)+0.2*LARGE(M3:P3,3)+0.2*Q3 -> 2562.9431 | M3: =IFERROR(VLOOKUP(K3, 'Duke 1'!$A$3:$B998,2, 0), 0) -> 3789.4737 | N3: =IFERROR(VLOOKUP(K3, 'Duke 2'!$A$3:$B998,2, 0), 0) -> 1500 | O3: =IFERROR(VLOOKUP(K3, 'Duke 3'!$A$3:$B998,2, 0), 0) -> 1777.7778 | P3: =IFERROR(VLOOKUP(K3, 'Duke 4'!$A$3:$B998,2, 0), 0) -> 1920 | Q3: =IFERROR(VLOOKUP(K3, Proof!$A$3:B998,2, 0), 0) -> 2472.7273
A4: =ROW()-1 -> 3 | B4: 2026mzhao | C4: =0.35*LARGE(D4:G4,1)+0.35*LARGE(D4:G4,2)+0.2*LARGE(D4:G4,3)+0.1*H4 -> 2266.2222 | D4: =IFERROR(VLOOKUP(B4, 'Duke 1'!A$3:$B$85,2, 0), 0) -> 1263.1579 | E4: =IFERROR(VLOOKUP(B4, 'Duke 2'!A$3:$B$522,2, 0), 0) -> 1500 | F4: =IFERROR(VLOOKUP(B4, 'Duke 3'!A$3:$B998,2, 0), 0) -> 1777.7778 | G4: =IFERROR(VLOOKUP(B4, 'Duke 4'!A$3:$B998,2, 0), 0) -> 3840 | H4: =IFERROR(VLOOKUP(B4, Proof!A$2:$B998,2, 0), 0) -> 0 | K4: 2027pdu | L4: =0.3*LARGE(M4:P4,1)+0.3*LARGE(M4:P4,2)+0.2*LARGE(M4:P4,3)+0.2*Q4 -> 2140.7422 | M4: =IFERROR(VLOOKUP(K4, 'Duke 1'!$A$3:$B998,2, 0), 0) -> 3157.8947 | N4: =IFERROR(VLOOKUP(K4, 'Duke 2'!$A$3:$B998,2, 0), 0) -> 1500 | O4: =IFERROR(VLOOKUP(K4, 'Duke 3'!$A$3:$B998,2, 0), 0) -> 1777.7778 | P4: =IFERROR(VLOOKUP(K4, 'Duke 4'!$A$3:$B998,2, 0), 0) -> 1920 | Q4: =IFERROR(VLOOKUP(K4, Proof!$A$3:B998,2, 0), 0) -> 1309.0909
A5: =ROW()-1 -> 4 | B5: 2027pdu | C5: =0.35*LARGE(D5:G5,1)+0.35*LARGE(D5:G5,2)+0.2*LARGE(D5:G5,3)+0.1*H5 -> 2263.7278 | D5: =IFERROR(VLOOKUP(B5, 'Duke 1'!A$3:$B$85,2, 0), 0) -> 3157.8947 | E5: =IFERROR(VLOOKUP(B5, 'Duke 2'!A$3:$B$522,2, 0), 0) -> 1500 | F5: =IFERROR(VLOOKUP(B5, 'Duke 3'!A$3:$B998,2, 0), 0) -> 1777.7778 | G5: =IFERROR(VLOOKUP(B5, 'Duke 4'!A$3:$B998,2, 0), 0) -> 1920 | H5: =IFERROR(VLOOKUP(B5, Proof!A$2:$B998,2, 0), 0) -> 1309.0909 | K5: 2026jma | L5: =0.3*LARGE(M5:P5,1)+0.3*LARGE(M5:P5,2)+0.2*LARGE(M5:P5,3)+0.2*Q5 -> 1998.5008 | M5: =IFERROR(VLOOKUP(K5, 'Duke 1'!$A$3:$B998,2, 0), 0) -> 2526.3158 | N5: =IFERROR(VLOOKUP(K5, 'Duke 2'!$A$3:$B998,2, 0), 0) -> 1500 | O5: =IFERROR(VLOOKUP(K5, 'Duke 3'!$A$3:$B998,2, 0), 0) -> 1777.7778 | P5: =IFERROR(VLOOKUP(K5, 'Duke 4'!$A$3:$B998,2, 0), 0) -> 960 | Q5: =IFERROR(VLOOKUP(K5, Proof!$A$3:B998,2, 0), 0) -> 2036.3636
A6: =ROW()-1 -> 5 | B6: 2026jma | C6: =0.35*LARGE(D6:G6,1)+0.35*LARGE(D6:G6,2)+0.2*LARGE(D6:G6,3)+0.1*H6 -> 2010.0691 | D6: =IFERROR(VLOOKUP(B6, 'Duke 1'!A$3:$B$85,2, 0), 0) -> 2526.3158 | E6: =IFERROR(VLOOKUP(B6, 'Duke 2'!A$3:$B$522,2, 0), 0) -> 1500 | F6: =IFERROR(VLOOKUP(B6, 'Duke 3'!A$3:$B998,2, 0), 0) -> 1777.7778 | G6: =IFERROR(VLOOKUP(B6, 'Duke 4'!A$3:$B998,2, 0), 0) -> 960 | H6: =IFERROR(VLOOKUP(B6, Proof!A$2:$B998,2, 0), 0) -> 2036.3636 | K6: 2026mzhao | L6: =0.3*LARGE(M6:P6,1)+0.3*LARGE(M6:P6,2)+0.2*LARGE(M6:P6,3)+0.2*Q6 -> 1985.3333 | M6: =IFERROR(VLOOKUP(K6, 'Duke 1'!$A$3:$B998,2, 0), 0) -> 1263.1579 | N6: =IFERROR(VLOOKUP(K6, 'Duke 2'!$A$3:$B998,2, 0), 0) -> 1500 | O6: =IFERROR(VLOOKUP(K6, 'Duke 3'!$A$3:$B998,2, 0), 0) -> 1777.7778 | P6: =IFERROR(VLOOKUP(K6, 'Duke 4'!$A$3:$B998,2, 0), 0) -> 3840 | Q6: =IFERROR(VLOOKUP(K6, Proof!$A$3:B998,2, 0), 0) -> 0
A7: =ROW()-1 -> 6 | B7: 2027smahmud | C7: =0.35*LARGE(D7:G7,1)+0.35*LARGE(D7:G7,2)+0.2*LARGE(D7:G7,3)+0.1*H7 -> 1905.3333 | D7: =IFERROR(VLOOKUP(B7, 'Duke 1'!A$3:$B$85,2, 0), 0) -> 0 | E7: =IFERROR(VLOOKUP(B7, 'Duke 2'!A$3:$B$522,2, 0), 0) -> 1500 | F7: =IFERROR(VLOOKUP(B7, 'Duke 3'!A$3:$B998,2, 0), 0) -> 2666.6667 | G7: =IFERROR(VLOOKUP(B7, 'Duke 4'!A$3:$B998,2, 0), 0) -> 1920 | H7: =IFERROR(VLOOKUP(B7, Proof!A$2:$B998,2, 0), 0) -> 0 | I7: sharahil moment | K7: 2027esombhat | L7: =0.3*LARGE(M7:P7,1)+0.3*LARGE(M7:P7,2)+0.2*LARGE(M7:P7,3)+0.2*Q7 -> 1778.0766 | M7: =IFERROR(VLOOKUP(K7, 'Duke 1'!$A$3:$B998,2, 0), 0) -> 2526.3158 | N7: =IFERROR(VLOOKUP(K7, 'Duke 2'!$A$3:$B998,2, 0), 0) -> 1500 | O7: =IFERROR(VLOOKUP(K7, 'Duke 3'!$A$3:$B998,2, 0), 0) -> 888.88889 | P7: =IFERROR(VLOOKUP(K7, 'Duke 4'!$A$3:$B998,2, 0), 0) -> 960 | Q7: =IFERROR(VLOOKUP(K7, Proof!$A$3:B998,2, 0), 0) -> 1890.9091
A8: =ROW()-1 -> 7 | B8: 2028szhang | C8: =0.35*LARGE(D8:G8,1)+0.35*LARGE(D8:G8,2)+0.2*LARGE(D8:G8,3)+0.1*H8 -> 1812.596 | D8: =IFERROR(VLOOKUP(B8, 'Duke 1'!A$3:$B$85,2, 0), 0) -> 631.57895 | E8: =IFERROR(VLOOKUP(B8, 'Duke 2'!A$3:$B$522,2, 0), 0) -> 1500 | F8: =IFERROR(VLOOKUP(B8, 'Duke 3'!A$3:$B998,2, 0), 0) -> 888.88889 | G8: =IFERROR(VLOOKUP(B8, 'Duke 4'!A$3:$B998,2, 0), 0) -> 2880 | H8: =IFERROR(VLOOKUP(B8, Proof!A$2:$B998,2, 0), 0) -> 1018.1818 | K8: 2028szhang | L8: =0.3*LARGE(M8:P8,1)+0.3*LARGE(M8:P8,2)+0.2*LARGE(M8:P8,3)+0.2*Q8 -> 1695.4141 | M8: =IFERROR(VLOOKUP(K8, 'Duke 1'!$A$3:$B998,2, 0), 0) -> 631.57895 | N8: =IFERROR(VLOOKUP(K8, 'Duke 2'!$A$3:$B998,2, 0), 0) -> 1500 | O8: =IFERROR(VLOOKUP(K8, 'Duke 3'!$A$3:$B998,2, 0), 0) -> 888.88889 | P8: =IFERROR(VLOOKUP(K8, 'Duke 4'!$A$3:$B998,2, 0), 0) -> 2880 | Q8: =IFERROR(VLOOKUP(K8, Proof!$A$3:B998,2, 0), 0) -> 1018.1818
A9: =ROW()-1 -> 8 | B9: 2027esombhat | C9: =0.35*LARGE(D9:G9,1)+0.35*LARGE(D9:G9,2)+0.2*LARGE(D9:G9,3)+0.1*H9 -> 1790.3014 | D9: =IFERROR(VLOOKUP(B9, 'Duke 1'!A$3:$B$85,2, 0), 0) -> 2526.3158 | E9: =IFERROR(VLOOKUP(B9, 'Duke 2'!A$3:$B$522,2, 0), 0) -> 1500 | F9: =IFERROR(VLOOKUP(B9, 'Duke 3'!A$3:$B998,2, 0), 0) -> 888.88889 | G9: =IFERROR(VLOOKUP(B9, 'Duke 4'!A$3:$B998,2, 0), 0) -> 960 | H9: =IFERROR(VLOOKUP(B9, Proof!A$2:$B998,2, 0), 0) -> 1890.9091 | K9: 2027smahmud | L9: =0.3*LARGE(M9:P9,1)+0.3*LARGE(M9:P9,2)+0.2*LARGE(M9:P9,3)+0.2*Q9 -> 1676 | M9: =IFERROR(VLOOKUP(K9, 'Duke 1'!$A$3:$B998,2, 0), 0) -> 0 | N9: =IFERROR(VLOOKUP(K9, 'Duke 2'!$A$3:$B998,2, 0), 0) -> 1500 | O9: =IFERROR(VLOOKUP(K9, 'Duke 3'!$A$3:$B998,2, 0), 0) -> 2666.6667 | P9: =IFERROR(VLOOKUP(K9, 'Duke 4'!$A$3:$B998,2, 0), 0) -> 1920 | Q9: =IFERROR(VLOOKUP(K9, Proof!$A$3:B998,2, 0), 0) -> 0
A10: =ROW()-1 -> 9 | B10: 2028mlin | C10: =0.35*LARGE(D10:G10,1)+0.35*LARGE(D10:G10,2)+0.2*LARGE(D10:G10,3)+0.1*H10 -> 1594.2222 | D10: =IFERROR(VLOOKUP(B10, 'Duke 1'!A$3:$B$85,2, 0), 0) -> 0 | E10: =IFERROR(VLOOKUP(B10, 'Duke 2'!A$3:$B$522,2, 0), 0) -> 1500 | F10: =IFERROR(VLOOKUP(B10, 'Duke 3'!A$3:$B998,2, 0), 0) -> 1777.7778 | G10: =IFERROR(VLOOKUP(B10, 'Duke 4'!A$3:$B998,2, 0), 0) -> 1920 | H10: =IFERROR(VLOOKUP(B10, Proof!A$2:$B998,2, 0), 0) -> 0 | K10: 2027ahao | L10: =0.3*LARGE(M10:P10,1)+0.3*LARGE(M10:P10,2)+0.2*LARGE(M10:P10,3)+0.2*Q10 -> 1585.0558 | M10: =IFERROR(VLOOKUP(K10, 'Duke 1'!$A$3:$B998,2, 0), 0) -> 1263.1579 | N10: =IFERROR(VLOOKUP(K10, 'Duke 2'!$A$3:$B998,2, 0), 0) -> 1500 | O10: =IFERROR(VLOOKUP(K10, 'Duke 3'!$A$3:$B998,2, 0), 0) -> 1777.7778 | P10: =IFERROR(VLOOKUP(K10, 'Duke 4'!$A$3:$B998,2, 0), 0) -> 960 | Q10: =IFERROR(VLOOKUP(K10, Proof!$A$3:B998,2, 0), 0) -> 1745.4545
A11: =ROW()-1 -> 10 | B11: 2027ahao | C11: =0.35*LARGE(D11:G11,1)+0.35*LARGE(D11:G11,2)+0.2*LARGE(D11:G11,3)+0.1*H11 -> 1574.3993 | D11: =IFERROR(VLOOKUP(B11, 'Duke 1'!A$3:$B$85,2, 0), 0) -> 1263.1579 | E11: =IFERROR(VLOOKUP(B11, 'Duke 2'!A$3:$B$522,2, 0), 0) -> 1500 | F11: =IFERROR(VLOOKUP(B11, 'Duke 3'!A$3:$B998,2, 0), 0) -> 1777.7778 | G11: =IFERROR(VLOOKUP(B11, 'Duke 4'!A$3:$B998,2, 0), 0) -> 960 | H11: =IFERROR(VLOOKUP(B11, Proof!A$2:$B998,2, 0), 0) -> 1745.4545 | K11: 2027itennyso | L11: =0.3*LARGE(M11:P11,1)+0.3*LARGE(M11:P11,2)+0.2*LARGE(M11:P11,3)+0.2*Q11 -> 1526.874 | M11: =IFERROR(VLOOKUP(K11, 'Duke 1'!$A$3:$B998,2, 0), 0) -> 1263.1579 | N11: =IFERROR(VLOOKUP(K11, 'Duke 2'!$A$3:$B998,2, 0), 0) -> 1500 | O11: =IFERROR(VLOOKUP(K11, 'Duke 3'!$A$3:$B998,2, 0), 0) -> 1777.7778 | P11: =IFERROR(VLOOKUP(K11, 'Duke 4'!$A$3:$B998,2, 0), 0) -> 960 | Q11: =IFERROR(VLOOKUP(K11, Proof!$A$3:B998,2, 0), 0) -> 1454.5455
A12: =ROW()-1 -> 11 | B12: 2027itennyso | C12: =0.35*LARGE(D12:G12,1)+0.35*LARGE(D12:G12,2)+0.2*LARGE(D12:G12,3)+0.1*H12 -> 1545.3083 | D12: =IFERROR(VLOOKUP(B12, 'Duke 1'!A$3:$B$85,2, 0), 0) -> 1263.1579 | E12: =IFERROR(VLOOKUP(B12, 'Duke 2'!A$3:$B$522,2, 0), 0) -> 1500 | F12: =IFERROR(VLOOKUP(B12, 'Duke 3'!A$3:$B998,2, 0), 0) -> 1777.7778 | G12: =IFERROR(VLOOKUP(B12, 'Duke 4'!A$3:$B998,2, 0), 0) -> 960 | H12: =IFERROR(VLOOKUP(B12, Proof!A$2:$B998,2, 0), 0) -> 1454.5455 | K12: 2027eguo | L12: =0.3*LARGE(M12:P12,1)+0.3*LARGE(M12:P12,2)+0.2*LARGE(M12:P12,3)+0.2*Q12 -> 1487.8309 | M12: =IFERROR(VLOOKUP(K12, 'Duke 1'!$A$3:$B998,2, 0), 0) -> 631.57895 | N12: =IFERROR(VLOOKUP(K12, 'Duke 2'!$A$3:$B998,2, 0), 0) -> 1500 | O12: =IFERROR(VLOOKUP(K12, 'Duke 3'!$A$3:$B998,2, 0), 0) -> 1777.7778 | P12: =IFERROR(VLOOKUP(K12, 'Duke 4'!$A$3:$B998,2, 0), 0) -> 0 | Q12: =IFERROR(VLOOKUP(K12, Proof!$A$3:B998,2, 0), 0) -> 1890.9091
A13: =ROW()-1 -> 12 | B13: 2027vcao | C13: =0.35*LARGE(D13:G13,1)+0.35*LARGE(D13:G13,2)+0.2*LARGE(D13:G13,3)+0.1*H13 -> 1477.3801 | D13: =IFERROR(VLOOKUP(B13, 'Duke 1'!A$3:$B$85,2, 0), 0) -> 1894.7368 | E13: =IFERROR(VLOOKUP(B13, 'Duke 2'!A$3:$B$522,2, 0), 0) -> 0 | F13: =IFERROR(VLOOKUP(B13, 'Duke 3'!A$3:$B998,2, 0), 0) -> 1777.7778 | G13: =IFERROR(VLOOKUP(B13, 'Duke 4'!A$3:$B998,2, 0), 0) -> 960 | H13: =IFERROR(VLOOKUP(B13, Proof!A$2:$B998,2, 0), 0) -> 0 | K13: 2028mlin | L13: =0.3*LARGE(M13:P13,1)+0.3*LARGE(M13:P13,2)+0.2*LARGE(M13:P13,3)+0.2*Q13 -> 1409.3333 | M13: =IFERROR(VLOOKUP(K13, 'Duke 1'!$A$3:$B998,2, 0), 0) -> 0 | N13: =IFERROR(VLOOKUP(K13, 'Duke 2'!$A$3:$B998,2, 0), 0) -> 1500 | O13: =IFERROR(VLOOKUP(K13, 'Duke 3'!$A$3:$B998,2, 0), 0) -> 1777.7778 | P13: =IFERROR(VLOOKUP(K13, 'Duke 4'!$A$3:$B998,2, 0), 0) -> 1920 | Q13: =IFERROR(VLOOKUP(K13, Proof!$A$3:B998,2, 0), 0) -> 0
A14: =ROW()-1 -> 13 | B14: 2027eguo | C14: =0.35*LARGE(D14:G14,1)+0.35*LARGE(D14:G14,2)+0.2*LARGE(D14:G14,3)+0.1*H14 -> 1462.6289 | D14: =IFERROR(VLOOKUP(B14, 'Duke 1'!A$3:$B$85,2, 0), 0) -> 631.57895 | E14: =IFERROR(VLOOKUP(B14, 'Duke 2'!A$3:$B$522,2, 0), 0) -> 1500 | F14: =IFERROR(VLOOKUP(B14, 'Duke 3'!A$3:$B998,2, 0), 0) -> 1777.7778 | G14: =IFERROR(VLOOKUP(B14, 'Duke 4'!A$3:$B998,2, 0), 0) -> 0 | H14: =IFERROR(VLOOKUP(B14, Proof!A$2:$B998,2, 0), 0) -> 1890.9091 | K14: 2027achu | L14: =0.3*LARGE(M14:P14,1)+0.3*LARGE(M14:P14,2)+0.2*LARGE(M14:P14,3)+0.2*Q14 -> 1385.0431 | M14: =IFERROR(VLOOKUP(K14, 'Duke 1'!$A$3:$B998,2, 0), 0) -> 631.57895 | N14: =IFERROR(VLOOKUP(K14, 'Duke 2'!$A$3:$B998,2, 0), 0) -> 1500 | O14: =IFERROR(VLOOKUP(K14, 'Duke 3'!$A$3:$B998,2, 0), 0) -> 0 | P14: =IFERROR(VLOOKUP(K14, 'Duke 4'!$A$3:$B998,2, 0), 0) -> 1920 | Q14: =IFERROR(VLOOKUP(K14, Proof!$A$3:B998,2, 0), 0) -> 1163.6364
A15: =ROW()-1 -> 14 | B15: 2027achu | C15: =0.35*LARGE(D15:G15,1)+0.35*LARGE(D15:G15,2)+0.2*LARGE(D15:G15,3)+0.1*H15 -> 1439.6794 | D15: =IFERROR(VLOOKUP(B15, 'Duke 1'!A$3:$B$85,2, 0), 0) -> 631.57895 | E15: =IFERROR(VLOOKUP(B15, 'Duke 2'!A$3:$B$522,2, 0), 0) -> 1500 | F15: =IFERROR(VLOOKUP(B15, 'Duke 3'!A$3:$B998,2, 0), 0) -> 0 | G15: =IFERROR(VLOOKUP(B15, 'Duke 4'!A$3:$B998,2, 0), 0) -> 1920 | H15: =IFERROR(VLOOKUP(B15, Proof!A$2:$B998,2, 0), 0) -> 1163.6364 | K15: 2027eshan | L15: =0.3*LARGE(M15:P15,1)+0.3*LARGE(M15:P15,2)+0.2*LARGE(M15:P15,3)+0.2*Q15 -> 1355.8161 | M15: =IFERROR(VLOOKUP(K15, 'Duke 1'!$A$3:$B998,2, 0), 0) -> 1263.1579 | N15: =IFERROR(VLOOKUP(K15, 'Duke 2'!$A$3:$B998,2, 0), 0) -> 1500 | O15: =IFERROR(VLOOKUP(K15, 'Duke 3'!$A$3:$B998,2, 0), 0) -> 888.88889 | P15: =IFERROR(VLOOKUP(K15, 'Duke 4'!$A$3:$B998,2, 0), 0) -> 0 | Q15: =IFERROR(VLOOKUP(K15, Proof!$A$3:B998,2, 0), 0) -> 1745.4545
A16: =ROW()-1 -> 15 | B16: 2026rsingh2 | C16: =0.35*LARGE(D16:G16,1)+0.35*LARGE(D16:G16,2)+0.2*LARGE(D16:G16,3)+0.1*H16 -> 1368.3131 | D16: =IFERROR(VLOOKUP(B16, 'Duke 1'!A$3:$B$85,2, 0), 0) -> 0 | E16: =IFERROR(VLOOKUP(B16, 'Duke 2'!A$3:$B$522,2, 0), 0) -> 1500 | F16: =IFERROR(VLOOKUP(B16, 'Duke 3'!A$3:$B998,2, 0), 0) -> 1777.7778 | G16: =IFERROR(VLOOKUP(B16, 'Duke 4'!A$3:$B998,2, 0), 0) -> 960 | H16: =IFERROR(VLOOKUP(B16, Proof!A$2:$B998,2, 0), 0) -> 290.90909 | K16: 2027vcao | L16: =0.3*LARGE(M16:P16,1)+0.3*LARGE(M16:P16,2)+0.2*LARGE(M16:P16,3)+0.2*Q16 -> 1293.7544 | M16: =IFERROR(VLOOKUP(K16, 'Duke 1'!$A$3:$B998,2, 0), 0) -> 1894.7368 | N16: =IFERROR(VLOOKUP(K16, 'Duke 2'!$A$3:$B998,2, 0), 0) -> 0 | O16: =IFERROR(VLOOKUP(K16, 'Duke 3'!$A$3:$B998,2, 0), 0) -> 1777.7778 | P16: =IFERROR(VLOOKUP(K16, 'Duke 4'!$A$3:$B998,2, 0), 0) -> 960 | Q16: =IFERROR(VLOOKUP(K16, Proof!$A$3:B998,2, 0), 0) -> 0
A17: =ROW()-1 -> 16 | B17: 2029adu | C17: =0.35*LARGE(D17:G17,1)+0.35*LARGE(D17:G17,2)+0.2*LARGE(D17:G17,3)+0.1*H17 -> 1353.7677 | D17: =IFERROR(VLOOKUP(B17, 'Duke 1'!A$3:$B$85,2, 0), 0) -> 631.57895 | E17: =IFERROR(VLOOKUP(B17, 'Duke 2'!A$3:$B$522,2, 0), 0) -> 1500 | F17: =IFERROR(VLOOKUP(B17, 'Duke 3'!A$3:$B998,2, 0), 0) -> 1777.7778 | G17: =IFERROR(VLOOKUP(B17, 'Duke 4'!A$3:$B998,2, 0), 0) -> 960 | H17: =IFERROR(VLOOKUP(B17, Proof!A$2:$B998,2, 0), 0) -> 145.45455 | K17: 2026rsingh2 | L17: =0.3*LARGE(M17:P17,1)+0.3*LARGE(M17:P17,2)+0.2*LARGE(M17:P17,3)+0.2*Q17 -> 1233.5152 | M17: =IFERROR(VLOOKUP(K17, 'Duke 1'!$A$3:$B998,2, 0), 0) -> 0 | N17: =IFERROR(VLOOKUP(K17, 'Duke 2'!$A$3:$B998,2, 0), 0) -> 1500 | O17: =IFERROR(VLOOKUP(K17, 'Duke 3'!$A$3:$B998,2, 0), 0) -> 1777.7778 | P17: =IFERROR(VLOOKUP(K17, 'Duke 4'!$A$3:$B998,2, 0), 0) -> 960 | Q17: =IFERROR(VLOOKUP(K17, Proof!$A$3:B998,2, 0), 0) -> 290.90909
A18: =ROW()-1 -> 17 | B18: 2029jdu | C18: =0.35*LARGE(D18:G18,1)+0.35*LARGE(D18:G18,2)+0.2*LARGE(D18:G18,3)+0.1*H18 -> 1339.2222 | D18: =IFERROR(VLOOKUP(B18, 'Duke 1'!A$3:$B$85,2, 0), 0) -> 0 | E18: =IFERROR(VLOOKUP(B18, 'Duke 2'!A$3:$B$522,2, 0), 0) -> 1500 | F18: =IFERROR(VLOOKUP(B18, 'Duke 3'!A$3:$B998,2, 0), 0) -> 1777.7778 | G18: =IFERROR(VLOOKUP(B18, 'Duke 4'!A$3:$B998,2, 0), 0) -> 960 | H18: =IFERROR(VLOOKUP(B18, Proof!A$2:$B998,2, 0), 0) -> 0 | K18: 2029adu | L18: =0.3*LARGE(M18:P18,1)+0.3*LARGE(M18:P18,2)+0.2*LARGE(M18:P18,3)+0.2*Q18 -> 1204.4242 | M18: =IFERROR(VLOOKUP(K18, 'Duke 1'!$A$3:$B998,2, 0), 0) -> 631.57895 | N18: =IFERROR(VLOOKUP(K18, 'Duke 2'!$A$3:$B998,2, 0), 0) -> 1500 | O18: =IFERROR(VLOOKUP(K18, 'Duke 3'!$A$3:$B998,2, 0), 0) -> 1777.7778 | P18: =IFERROR(VLOOKUP(K18, 'Duke 4'!$A$3:$B998,2, 0), 0) -> 960 | Q18: =IFERROR(VLOOKUP(K18, Proof!$A$3:B998,2, 0), 0) -> 145.45455
A19: =ROW()-1 -> 18 | B19: 2027eshan | C19: =0.35*LARGE(D19:G19,1)+0.35*LARGE(D19:G19,2)+0.2*LARGE(D19:G19,3)+0.1*H19 -> 1319.4285 | D19: =IFERROR(VLOOKUP(B19, 'Duke 1'!A$3:$B$85,2, 0), 0) -> 1263.1579 | E19: =IFERROR(VLOOKUP(B19, 'Duke 2'!A$3:$B$522,2, 0), 0) -> 1500 | F19: =IFERROR(VLOOKUP(B19, 'Duke 3'!A$3:$B998,2, 0), 0) -> 888.88889 | G19: =IFERROR(VLOOKUP(B19, 'Duke 4'!A$3:$B998,2, 0), 0) -> 0 | H19: =IFERROR(VLOOKUP(B19, Proof!A$2:$B998,2, 0), 0) -> 1745.4545 | K19: 2029jdu | L19: =0.3*LARGE(M19:P19,1)+0.3*LARGE(M19:P19,2)+0.2*LARGE(M19:P19,3)+0.2*Q19 -> 1175.3333 | M19: =IFERROR(VLOOKUP(K19, 'Duke 1'!$A$3:$B998,2, 0), 0) -> 0 | N19: =IFERROR(VLOOKUP(K19, 'Duke 2'!$A$3:$B998,2, 0), 0) -> 1500 | O19: =IFERROR(VLOOKUP(K19, 'Duke 3'!$A$3:$B998,2, 0), 0) -> 1777.7778 | P19: =IFERROR(VLOOKUP(K19, 'Duke 4'!$A$3:$B998,2, 0), 0) -> 960 | Q19: =IFERROR(VLOOKUP(K19, Proof!$A$3:B998,2, 0), 0) -> 0
A20: =ROW()-1 -> 19 | B20: 2029nmaloney | C20: =0.35*LARGE(D20:G20,1)+0.35*LARGE(D20:G20,2)+0.2*LARGE(D20:G20,3)+0.1*H20 -> 1271.0526 | D20: =IFERROR(VLOOKUP(B20, 'Duke 1'!A$3:$B$85,2, 0), 0) -> 631.57895 | E20: =IFERROR(VLOOKUP(B20, 'Duke 2'!A$3:$B$522,2, 0), 0) -> 3000 | F20: =IFERROR(VLOOKUP(B20, 'Duke 3'!A$3:$B998,2, 0), 0) -> 0 | G20: =IFERROR(VLOOKUP(B20, 'Duke 4'!A$3:$B998,2, 0), 0) -> 0 | H20: =IFERROR(VLOOKUP(B20, Proof!A$2:$B998,2, 0), 0) -> 0 | K20: 2028yli | L20: =0.3*LARGE(M20:P20,1)+0.3*LARGE(M20:P20,2)+0.2*LARGE(M20:P20,3)+0.2*Q20 -> 1148.5051 | M20: =IFERROR(VLOOKUP(K20, 'Duke 1'!$A$3:$B998,2, 0), 0) -> 631.57895 | N20: =IFERROR(VLOOKUP(K20, 'Duke 2'!$A$3:$B998,2, 0), 0) -> 1500 | O20: =IFERROR(VLOOKUP(K20, 'Duke 3'!$A$3:$B998,2, 0), 0) -> 888.88889 | P20: =IFERROR(VLOOKUP(K20, 'Duke 4'!$A$3:$B998,2, 0), 0) -> 960 | Q20: =IFERROR(VLOOKUP(K20, Proof!$A$3:B998,2, 0), 0) -> 1163.6364
A21: =ROW()-1 -> 20 | B21: 2029sbi | C21: =0.35*LARGE(D21:G21,1)+0.35*LARGE(D21:G21,2)+0.2*LARGE(D21:G21,3)+0.1*H21 -> 1159.1053 | D21: =IFERROR(VLOOKUP(B21, 'Duke 1'!A$3:$B$85,2, 0), 0) -> 1263.1579 | E21: =IFERROR(VLOOKUP(B21, 'Duke 2'!A$3:$B$522,2, 0), 0) -> 1500 | F21: =IFERROR(VLOOKUP(B21, 'Duke 3'!A$3:$B998,2, 0), 0) -> 888.88889 | G21: =IFERROR(VLOOKUP(B21, 'Duke 4'!A$3:$B998,2, 0), 0) -> 960 | H21: =IFERROR(VLOOKUP(B21, Proof!A$2:$B998,2, 0), 0) -> 0 | K21: 2027achakrav | L21: =0.3*LARGE(M21:P21,1)+0.3*LARGE(M21:P21,2)+0.2*LARGE(M21:P21,3)+0.2*Q21 -> 1148.5051 | M21: =IFERROR(VLOOKUP(K21, 'Duke 1'!$A$3:$B998,2, 0), 0) -> 631.57895 | N21: =IFERROR(VLOOKUP(K21, 'Duke 2'!$A$3:$B998,2, 0), 0) -> 1500 | O21: =IFERROR(VLOOKUP(K21, 'Duke 3'!$A$3:$B998,2, 0), 0) -> 888.88889 | P21: =IFERROR(VLOOKUP(K21, 'Duke 4'!$A$3:$B998,2, 0), 0) -> 960 | Q21: =IFERROR(VLOOKUP(K21, Proof!$A$3:B998,2, 0), 0) -> 1163.6364
A22: =ROW()-1 -> 21 | B22: 2028yli | C22: =0.35*LARGE(D22:G22,1)+0.35*LARGE(D22:G22,2)+0.2*LARGE(D22:G22,3)+0.1*H22 -> 1155.1414 | D22: =IFERROR(VLOOKUP(B22, 'Duke 1'!A$3:$B$85,2, 0), 0) -> 631.57895 | E22: =IFERROR(VLOOKUP(B22, 'Duke 2'!A$3:$B$522,2, 0), 0) -> 1500 | F22: =IFERROR(VLOOKUP(B22, 'Duke 3'!A$3:$B998,2, 0), 0) -> 888.88889 | G22: =IFERROR(VLOOKUP(B22, 'Duke 4'!A$3:$B998,2, 0), 0) -> 960 | H22: =IFERROR(VLOOKUP(B22, Proof!A$2:$B998,2, 0), 0) -> 1163.6364 | K22: 2029wli | L22: =0.3*LARGE(M22:P22,1)+0.3*LARGE(M22:P22,2)+0.2*LARGE(M22:P22,3)+0.2*Q22 -> 1119.4141 | M22: =IFERROR(VLOOKUP(K22, 'Duke 1'!$A$3:$B998,2, 0), 0) -> 631.57895 | N22: =IFERROR(VLOOKUP(K22, 'Duke 2'!$A$3:$B998,2, 0), 0) -> 1500 | O22: =IFERROR(VLOOKUP(K22, 'Duke 3'!$A$3:$B998,2, 0), 0) -> 888.88889 | P22: =IFERROR(VLOOKUP(K22, 'Duke 4'!$A$3:$B998,2, 0), 0) -> 960 | Q22: =IFERROR(VLOOKUP(K22, Proof!$A$3:B998,2, 0), 0) -> 1018.1818
A23: =ROW()-1 -> 22 | B23: 2027achakrav | C23: =0.35*LARGE(D23:G23,1)+0.35*LARGE(D23:G23,2)+0.2*LARGE(D23:G23,3)+0.1*H23 -> 1155.1414 | D23: =IFERROR(VLOOKUP(B23, 'Duke 1'!A$3:$B$85,2, 0), 0) -> 631.57895 | E23: =IFERROR(VLOOKUP(B23, 'Duke 2'!A$3:$B$522,2, 0), 0) -> 1500 | F23: =IFERROR(VLOOKUP(B23, 'Duke 3'!A$3:$B998,2, 0), 0) -> 888.88889 | G23: =IFERROR(VLOOKUP(B23, 'Duke 4'!A$3:$B998,2, 0), 0) -> 960 | H23: =IFERROR(VLOOKUP(B23, Proof!A$2:$B998,2, 0), 0) -> 1163.6364 | K23: 2029gbatkhuu | L23: =0.3*LARGE(M23:P23,1)+0.3*LARGE(M23:P23,2)+0.2*LARGE(M23:P23,3)+0.2*Q23 -> 1119.4141 | M23: =IFERROR(VLOOKUP(K23, 'Duke 1'!$A$3:$B998,2, 0), 0) -> 0 | N23: =IFERROR(VLOOKUP(K23, 'Duke 2'!$A$3:$B998,2, 0), 0) -> 1500 | O23: =IFERROR(VLOOKUP(K23, 'Duke 3'!$A$3:$B998,2, 0), 0) -> 888.88889 | P23: =IFERROR(VLOOKUP(K23, 'Duke 4'!$A$3:$B998,2, 0), 0) -> 960 | Q23: =IFERROR(VLOOKUP(K23, Proof!$A$3:B998,2, 0), 0) -> 1018.1818
A24: =ROW()-1 -> 23 | B24: 2028ktabakov | C24: =0.35*LARGE(D24:G24,1)+0.35*LARGE(D24:G24,2)+0.2*LARGE(D24:G24,3)+0.1*H24 -> 1147.2222 | D24: =IFERROR(VLOOKUP(B24, 'Duke 1'!A$3:$B$85,2, 0), 0) -> 0 | E24: =IFERROR(VLOOKUP(B24, 'Duke 2'!A$3:$B$522,2, 0), 0) -> 1500 | F24: =IFERROR(VLOOKUP(B24, 'Duke 3'!A$3:$B998,2, 0), 0) -> 1777.7778 | G24: =IFERROR(VLOOKUP(B24, 'Duke 4'!A$3:$B998,2, 0), 0) -> 0 | H24: =IFERROR(VLOOKUP(B24, Proof!A$2:$B998,2, 0), 0) -> 0 | K24: 2026owu | L24: =0.3*LARGE(M24:P24,1)+0.3*LARGE(M24:P24,2)+0.2*LARGE(M24:P24,3)+0.2*Q24 -> 1119.4141 | M24: =IFERROR(VLOOKUP(K24, 'Duke 1'!$A$3:$B998,2, 0), 0) -> 631.57895 | N24: =IFERROR(VLOOKUP(K24, 'Duke 2'!$A$3:$B998,2, 0), 0) -> 1500 | O24: =IFERROR(VLOOKUP(K24, 'Duke 3'!$A$3:$B998,2, 0), 0) -> 888.88889 | P24: =IFERROR(VLOOKUP(K24, 'Duke 4'!$A$3:$B998,2, 0), 0) -> 960 | Q24: =IFERROR(VLOOKUP(K24, Proof!$A$3:B998,2, 0), 0) -> 1018.1818
A25: =ROW()-1 -> 24 | B25: 2029wli | C25: =0.35*LARGE(D25:G25,1)+0.35*LARGE(D25:G25,2)+0.2*LARGE(D25:G25,3)+0.1*H25 -> 1140.596 | D25: =IFERROR(VLOOKUP(B25, 'Duke 1'!A$3:$B$85,2, 0), 0) -> 631.57895 | E25: =IFERROR(VLOOKUP(B25, 'Duke 2'!A$3:$B$522,2, 0), 0) -> 1500 | F25: =IFERROR(VLOOKUP(B25, 'Duke 3'!A$3:$B998,2, 0), 0) -> 888.88889 | G25: =IFERROR(VLOOKUP(B25, 'Duke 4'!A$3:$B998,2, 0), 0) -> 960 | H25: =IFERROR(VLOOKUP(B25, Proof!A$2:$B998,2, 0), 0) -> 1018.1818 | K25: 2029nmaloney | L25: =0.3*LARGE(M25:P25,1)+0.3*LARGE(M25:P25,2)+0.2*LARGE(M25:P25,3)+0.2*Q25 -> 1089.4737 | M25: =IFERROR(VLOOKUP(K25, 'Duke 1'!$A$3:$B998,2, 0), 0) -> 631.57895 | N25: =IFERROR(VLOOKUP(K25, 'Duke 2'!$A$3:$B998,2, 0), 0) -> 3000 | O25: =IFERROR(VLOOKUP(K25, 'Duke 3'!$A$3:$B998,2, 0), 0) -> 0 | P25: =IFERROR(VLOOKUP(K25, 'Duke 4'!$A$3:$B998,2, 0), 0) -> 0 | Q25: =IFERROR(VLOOKUP(K25, Proof!$A$3:B998,2, 0), 0) -> 0
A26: =ROW()-1 -> 25 | B26: 2029gbatkhuu | C26: =0.35*LARGE(D26:G26,1)+0.35*LARGE(D26:G26,2)+0.2*LARGE(D26:G26,3)+0.1*H26 -> 1140.596 | D26: =IFERROR(VLOOKUP(B26, 'Duke 1'!A$3:$B$85,2, 0), 0) -> 0 | E26: =IFERROR(VLOOKUP(B26, 'Duke 2'!A$3:$B$522,2, 0), 0) -> 1500 | F26: =IFERROR(VLOOKUP(B26, 'Duke 3'!A$3:$B998,2, 0), 0) -> 888.88889 | G26: =IFERROR(VLOOKUP(B26, 'Duke 4'!A$3:$B998,2, 0), 0) -> 960 | H26: =IFERROR(VLOOKUP(B26, Proof!A$2:$B998,2, 0), 0) -> 1018.1818 | K26: 2029sbi | L26: =0.3*LARGE(M26:P26,1)+0.3*LARGE(M26:P26,2)+0.2*LARGE(M26:P26,3)+0.2*Q26 -> 1020.9474 | M26: =IFERROR(VLOOKUP(K26, 'Duke 1'!$A$3:$B998,2, 0), 0) -> 1263.1579 | N26: =IFERROR(VLOOKUP(K26, 'Duke 2'!$A$3:$B998,2, 0), 0) -> 1500 | O26: =IFERROR(VLOOKUP(K26, 'Duke 3'!$A$3:$B998,2, 0), 0) -> 888.88889 | P26: =IFERROR(VLOOKUP(K26, 'Duke 4'!$A$3:$B998,2, 0), 0) -> 960 | Q26: =IFERROR(VLOOKUP(K26, Proof!$A$3:B998,2, 0), 0) -> 0
A27: =ROW()-1 -> 26 | B27: 2026owu | C27: =0.35*LARGE(D27:G27,1)+0.35*LARGE(D27:G27,2)+0.2*LARGE(D27:G27,3)+0.1*H27 -> 1140.596 | D27: =IFERROR(VLOOKUP(B27, 'Duke 1'!A$3:$B$85,2, 0), 0) -> 631.57895 | E27: =IFERROR(VLOOKUP(B27, 'Duke 2'!A$3:$B$522,2, 0), 0) -> 1500 | F27: =IFERROR(VLOOKUP(B27, 'Duke 3'!A$3:$B998,2, 0), 0) -> 888.88889 | G27: =IFERROR(VLOOKUP(B27, 'Duke 4'!A$3:$B998,2, 0), 0) -> 960 | H27: =IFERROR(VLOOKUP(B27, Proof!A$2:$B998,2, 0), 0) -> 1018.1818 | J27: rip paul | K27: 2027pyoo | L27: =0.3*LARGE(M27:P27,1)+0.3*LARGE(M27:P27,2)+0.2*LARGE(M27:P27,3)+0.2*Q27 -> 1020.1212 | M27: =IFERROR(VLOOKUP(K27, 'Duke 1'!$A$3:$B998,2, 0), 0) -> 0 | N27: =IFERROR(VLOOKUP(K27, 'Duke 2'!$A$3:$B998,2, 0), 0) -> 0 | O27: =IFERROR(VLOOKUP(K27, 'Duke 3'!$A$3:$B998,2, 0), 0) -> 888.88889 | P27: =IFERROR(VLOOKUP(K27, 'Duke 4'!$A$3:$B998,2, 0), 0) -> 960 | Q27: =IFERROR(VLOOKUP(K27, Proof!$A$3:B998,2, 0), 0) -> 2327.2727
A28: =ROW()-1 -> 27 | B28: 2028gkeeler | C28: =0.35*LARGE(D28:G28,1)+0.35*LARGE(D28:G28,2)+0.2*LARGE(D28:G28,3)+0.1*H28 -> 1038.7778 | D28: =IFERROR(VLOOKUP(B28, 'Duke 1'!A$3:$B$85,2, 0), 0) -> 0 | E28: =IFERROR(VLOOKUP(B28, 'Duke 2'!A$3:$B$522,2, 0), 0) -> 1500 | F28: =IFERROR(VLOOKUP(B28, 'Duke 3'!A$3:$B998,2, 0), 0) -> 888.88889 | G28: =IFERROR(VLOOKUP(B28, 'Duke 4'!A$3:$B998,2, 0), 0) -> 960 | H28: =IFERROR(VLOOKUP(B28, Proof!A$2:$B998,2, 0), 0) -> 0 | K28: 2028ktabakov | L28: =0.3*LARGE(M28:P28,1)+0.3*LARGE(M28:P28,2)+0.2*LARGE(M28:P28,3)+0.2*Q28 -> 983.33333 | M28: =IFERROR(VLOOKUP(K28, 'Duke 1'!$A$3:$B998,2, 0), 0) -> 0 | N28: =IFERROR(VLOOKUP(K28, 'Duke 2'!$A$3:$B998,2, 0), 0) -> 1500 | O28: =IFERROR(VLOOKUP(K28, 'Duke 3'!$A$3:$B998,2, 0), 0) -> 1777.7778 | P28: =IFERROR(VLOOKUP(K28, 'Duke 4'!$A$3:$B998,2, 0), 0) -> 0 | Q28: =IFERROR(VLOOKUP(K28, Proof!$A$3:B998,2, 0), 0) -> 0
A29: =ROW()-1 -> 28 | B29: 2027mbu | C29: =0.35*LARGE(D29:G29,1)+0.35*LARGE(D29:G29,2)+0.2*LARGE(D29:G29,3)+0.1*H29 -> 1038.7778 | D29: =IFERROR(VLOOKUP(B29, 'Duke 1'!A$3:$B$85,2, 0), 0) -> 631.57895 | E29: =IFERROR(VLOOKUP(B29, 'Duke 2'!A$3:$B$522,2, 0), 0) -> 1500 | F29: =IFERROR(VLOOKUP(B29, 'Duke 3'!A$3:$B998,2, 0), 0) -> 888.88889 | G29: =IFERROR(VLOOKUP(B29, 'Duke 4'!A$3:$B998,2, 0), 0) -> 960 | H29: =IFERROR(VLOOKUP(B29, Proof!A$2:$B998,2, 0), 0) -> 0 | K29: 2028gkeeler | L29: =0.3*LARGE(M29:P29,1)+0.3*LARGE(M29:P29,2)+0.2*LARGE(M29:P29,3)+0.2*Q29 -> 915.77778 | M29: =IFERROR(VLOOKUP(K29, 'Duke 1'!$A$3:$B998,2, 0), 0) -> 0 | N29: =IFERROR(VLOOKUP(K29, 'Duke 2'!$A$3:$B998,2, 0), 0) -> 1500 | O29: =IFERROR(VLOOKUP(K29, 'Duke 3'!$A$3:$B998,2, 0), 0) -> 888.88889 | P29: =IFERROR(VLOOKUP(K29, 'Duke 4'!$A$3:$B998,2, 0), 0) -> 960 | Q29: =IFERROR(VLOOKUP(K29, Proof!$A$3:B998,2, 0), 0) -> 0
A30: =ROW()-1 -> 29 | B30: 2027eqiu | C30: =0.35*LARGE(D30:G30,1)+0.35*LARGE(D30:G30,2)+0.2*LARGE(D30:G30,3)+0.1*H30 -> 1038.7778 | D30: =IFERROR(VLOOKUP(B30, 'Duke 1'!A$3:$B$85,2, 0), 0) -> 631.57895 | E30: =IFERROR(VLOOKUP(B30, 'Duke 2'!A$3:$B$522,2, 0), 0) -> 1500 | F30: =IFERROR(VLOOKUP(B30, 'Duke 3'!A$3:$B998,2, 0), 0) -> 888.88889 | G30: =IFERROR(VLOOKUP(B30, 'Duke 4'!A$3:$B998,2, 0), 0) -> 960 | H30: =IFERROR(VLOOKUP(B30, Proof!A$2:$B998,2, 0), 0) -> 0 | K30: 2027mbu | L30: =0.3*LARGE(M30:P30,1)+0.3*LARGE(M30:P30,2)+0.2*LARGE(M30:P30,3)+0.2*Q30 -> 915.77778 | M30: =IFERROR(VLOOKUP(K30, 'Duke 1'!$A$3:$B998,2, 0), 0) -> 631.57895 | N30: =IFERROR(VLOOKUP(K30, 'Duke 2'!$A$3:$B998,2, 0), 0) -> 1500 | O30: =IFERROR(VLOOKUP(K30, 'Duke 3'!$A$3:$B998,2, 0), 0) -> 888.88889 | P30: =IFERROR(VLOOKUP(K30, 'Duke 4'!$A$3:$B998,2, 0), 0) -> 960 | Q30: =IFERROR(VLOOKUP(K30, Proof!$A$3:B998,2, 0), 0) -> 0
A31: =ROW()-1 -> 30 | B31: 2026cmorimot | C31: =0.35*LARGE(D31:G31,1)+0.35*LARGE(D31:G31,2)+0.2*LARGE(D31:G31,3)+0.1*H31 -> 1038.7778 | D31: =IFERROR(VLOOKUP(B31, 'Duke 1'!A$3:$B$85,2, 0), 0) -> 0 | E31: =IFERROR(VLOOKUP(B31, 'Duke 2'!A$3:$B$522,2, 0), 0) -> 1500 | F31: =IFERROR(VLOOKUP(B31, 'Duke 3'!A$3:$B998,2, 0), 0) -> 888.88889 | G31: =IFERROR(VLOOKUP(B31, 'Duke 4'!A$3:$B998,2, 0), 0) -> 960 | H31: =IFERROR(VLOOKUP(B31, Proof!A$2:$B998,2, 0), 0) -> 0 | K31: 2027eqiu | L31: =0.3*LARGE(M31:P31,1)+0.3*LARGE(M31:P31,2)+0.2*LARGE(M31:P31,3)+0.2*Q31 -> 915.77778 | M31: =IFERROR(VLOOKUP(K31, 'Duke 1'!$A$3:$B998,2, 0), 0) -> 631.57895 | N31: =IFERROR(VLOOKUP(K31, 'Duke 2'!$A$3:$B998,2, 0), 0) -> 1500 | O31: =IFERROR(VLOOKUP(K31, 'Duke 3'!$A$3:$B998,2, 0), 0) -> 888.88889 | P31: =IFERROR(VLOOKUP(K31, 'Duke 4'!$A$3:$B998,2, 0), 0) -> 960 | Q31: =IFERROR(VLOOKUP(K31, Proof!$A$3:B998,2, 0), 0) -> 0
A32: =ROW()-1 -> 31 | B32: 2027sbisht | C32: =0.35*LARGE(D32:G32,1)+0.35*LARGE(D32:G32,2)+0.2*LARGE(D32:G32,3)+0.1*H32 -> 987.31579 | D32: =IFERROR(VLOOKUP(B32, 'Duke 1'!A$3:$B$85,2, 0), 0) -> 631.57895 | E32: =IFERROR(VLOOKUP(B32, 'Duke 2'!A$3:$B$522,2, 0), 0) -> 1500 | F32: =IFERROR(VLOOKUP(B32, 'Duke 3'!A$3:$B998,2, 0), 0) -> 0 | G32: =IFERROR(VLOOKUP(B32, 'Duke 4'!A$3:$B998,2, 0), 0) -> 960 | H32: =IFERROR(VLOOKUP(B32, Proof!A$2:$B998,2, 0), 0) -> 0 | K32: 2026cmorimot | L32: =0.3*LARGE(M32:P32,1)+0.3*LARGE(M32:P32,2)+0.2*LARGE(M32:P32,3)+0.2*Q32 -> 915.77778 | M32: =IFERROR(VLOOKUP(K32, 'Duke 1'!$A$3:$B998,2, 0), 0) -> 0 | N32: =IFERROR(VLOOKUP(K32, 'Duke 2'!$A$3:$B998,2, 0), 0) -> 1500 | O32: =IFERROR(VLOOKUP(K32, 'Duke 3'!$A$3:$B998,2, 0), 0) -> 888.88889 | P32: =IFERROR(VLOOKUP(K32, 'Duke 4'!$A$3:$B998,2, 0), 0) -> 960 | Q32: =IFERROR(VLOOKUP(K32, Proof!$A$3:B998,2, 0), 0) -> 0
A33: =ROW()-1 -> 32 | B33: 2027nliang | C33: =0.35*LARGE(D33:G33,1)+0.35*LARGE(D33:G33,2)+0.2*LARGE(D33:G33,3)+0.1*H33 -> 987.31579 | D33: =IFERROR(VLOOKUP(B33, 'Duke 1'!A$3:$B$85,2, 0), 0) -> 631.57895 | E33: =IFERROR(VLOOKUP(B33, 'Duke 2'!A$3:$B$522,2, 0), 0) -> 1500 | F33: =IFERROR(VLOOKUP(B33, 'Duke 3'!A$3:$B998,2, 0), 0) -> 0 | G33: =IFERROR(VLOOKUP(B33, 'Duke 4'!A$3:$B998,2, 0), 0) -> 960 | H33: =IFERROR(VLOOKUP(B33, Proof!A$2:$B998,2, 0), 0) -> 0 | K33: 2028athota | L33: =0.3*LARGE(M33:P33,1)+0.3*LARGE(M33:P33,2)+0.2*LARGE(M33:P33,3)+0.2*Q33 -> 872.07337 | M33: =IFERROR(VLOOKUP(K33, 'Duke 1'!$A$3:$B998,2, 0), 0) -> 631.57895 | N33: =IFERROR(VLOOKUP(K33, 'Duke 2'!$A$3:$B998,2, 0), 0) -> 1500 | O33: =IFERROR(VLOOKUP(K33, 'Duke 3'!$A$3:$B998,2, 0), 0) -> 888.88889 | P33: =IFERROR(VLOOKUP(K33, 'Duke 4'!$A$3:$B998,2, 0), 0) -> 0 | Q33: =IFERROR(VLOOKUP(K33, Proof!$A$3:B998,2, 0), 0) -> 145.45455
A34: =ROW()-1 -> 33 | B34: 2028athota | C34: =0.35*LARGE(D34:G34,1)+0.35*LARGE(D34:G34,2)+0.2*LARGE(D34:G34,3)+0.1*H34 -> 976.97236 | D34: =IFERROR(VLOOKUP(B34, 'Duke 1'!A$3:$B$85,2, 0), 0) -> 631.57895 | E34: =IFERROR(VLOOKUP(B34, 'Duke 2'!A$3:$B$522,2, 0), 0) -> 1500 | F34: =IFERROR(VLOOKUP(B34, 'Duke 3'!A$3:$B998,2, 0), 0) -> 888.88889 | G34: =IFERROR(VLOOKUP(B34, 'Duke 4'!A$3:$B998,2, 0), 0) -> 0 | H34: =IFERROR(VLOOKUP(B34, Proof!A$2:$B998,2, 0), 0) -> 145.45455 | K34: 2027sbisht | L34: =0.3*LARGE(M34:P34,1)+0.3*LARGE(M34:P34,2)+0.2*LARGE(M34:P34,3)+0.2*Q34 -> 864.31579 | M34: =IFERROR(VLOOKUP(K34, 'Duke 1'!$A$3:$B998,2, 0), 0) -> 631.57895 | N34: =IFERROR(VLOOKUP(K34, 'Duke 2'!$A$3:$B998,2, 0), 0) -> 1500 | O34: =IFERROR(VLOOKUP(K34, 'Duke 3'!$A$3:$B998,2, 0), 0) -> 0 | P34: =IFERROR(VLOOKUP(K34, 'Duke 4'!$A$3:$B998,2, 0), 0) -> 960 | Q34: =IFERROR(VLOOKUP(K34, Proof!$A$3:B998,2, 0), 0) -> 0
A35: =ROW()-1 -> 34 | B35: 2027pyoo | C35: =0.35*LARGE(D35:G35,1)+0.35*LARGE(D35:G35,2)+0.2*LARGE(D35:G35,3)+0.1*H35 -> 879.83838 | D35: =IFERROR(VLOOKUP(B35, 'Duke 1'!A$3:$B$85,2, 0), 0) -> 0 | E35: =IFERROR(VLOOKUP(B35, 'Duke 2'!A$3:$B$522,2, 0), 0) -> 0 | F35: =IFERROR(VLOOKUP(B35, 'Duke 3'!A$3:$B998,2, 0), 0) -> 888.88889 | G35: =IFERROR(VLOOKUP(B35, 'Duke 4'!A$3:$B998,2, 0), 0) -> 960 | H35: =IFERROR(VLOOKUP(B35, Proof!A$2:$B998,2, 0), 0) -> 2327.2727 | K35: 2027nliang | L35: =0.3*LARGE(M35:P35,1)+0.3*LARGE(M35:P35,2)+0.2*LARGE(M35:P35,3)+0.2*Q35 -> 864.31579 | M35: =IFERROR(VLOOKUP(K35, 'Duke 1'!$A$3:$B998,2, 0), 0) -> 631.57895 | N35: =IFERROR(VLOOKUP(K35, 'Duke 2'!$A$3:$B998,2, 0), 0) -> 1500 | O35: =IFERROR(VLOOKUP(K35, 'Duke 3'!$A$3:$B998,2, 0), 0) -> 0 | P35: =IFERROR(VLOOKUP(K35, 'Duke 4'!$A$3:$B998,2, 0), 0) -> 960 | Q35: =IFERROR(VLOOKUP(K35, Proof!$A$3:B998,2, 0), 0) -> 0
A36: =ROW()-1 -> 35 | B36: 2029mkim1 | C36: =0.35*LARGE(D36:G36,1)+0.35*LARGE(D36:G36,2)+0.2*LARGE(D36:G36,3)+0.1*H36 -> 875.54545 | D36: =IFERROR(VLOOKUP(B36, 'Duke 1'!A$3:$B$85,2, 0), 0) -> 0 | E36: =IFERROR(VLOOKUP(B36, 'Duke 2'!A$3:$B$522,2, 0), 0) -> 1500 | F36: =IFERROR(VLOOKUP(B36, 'Duke 3'!A$3:$B998,2, 0), 0) -> 0 | G36: =IFERROR(VLOOKUP(B36, 'Duke 4'!A$3:$B998,2, 0), 0) -> 960 | H36: =IFERROR(VLOOKUP(B36, Proof!A$2:$B998,2, 0), 0) -> 145.45455 | K36: 2028aliu | L36: =0.3*LARGE(M36:P36,1)+0.3*LARGE(M36:P36,2)+0.2*LARGE(M36:P36,3)+0.2*Q36 -> 814.54545 | M36: =IFERROR(VLOOKUP(K36, 'Duke 1'!$A$3:$B998,2, 0), 0) -> 0 | N36: =IFERROR(VLOOKUP(K36, 'Duke 2'!$A$3:$B998,2, 0), 0) -> 0 | O36: =IFERROR(VLOOKUP(K36, 'Duke 3'!$A$3:$B998,2, 0), 0) -> 0 | P36: =IFERROR(VLOOKUP(K36, 'Duke 4'!$A$3:$B998,2, 0), 0) -> 0 | Q36: =IFERROR(VLOOKUP(K36, Proof!$A$3:B998,2, 0), 0) -> 4072.7273
A37: =ROW()-1 -> 36 | B37: 2029achennad | C37: =0.35*LARGE(D37:G37,1)+0.35*LARGE(D37:G37,2)+0.2*LARGE(D37:G37,3)+0.1*H37 -> 875.54545 | D37: =IFERROR(VLOOKUP(B37, 'Duke 1'!A$3:$B$85,2, 0), 0) -> 0 | E37: =IFERROR(VLOOKUP(B37, 'Duke 2'!A$3:$B$522,2, 0), 0) -> 1500 | F37: =IFERROR(VLOOKUP(B37, 'Duke 3'!A$3:$B998,2, 0), 0) -> 0 | G37: =IFERROR(VLOOKUP(B37, 'Duke 4'!A$3:$B998,2, 0), 0) -> 960 | H37: =IFERROR(VLOOKUP(B37, Proof!A$2:$B998,2, 0), 0) -> 145.45455 | K37: 2029mkim1 | L37: =0.3*LARGE(M37:P37,1)+0.3*LARGE(M37:P37,2)+0.2*LARGE(M37:P37,3)+0.2*Q37 -> 767.09091 | M37: =IFERROR(VLOOKUP(K37, 'Duke 1'!$A$3:$B998,2, 0), 0) -> 0 | N37: =IFERROR(VLOOKUP(K37, 'Duke 2'!$A$3:$B998,2, 0), 0) -> 1500 | O37: =IFERROR(VLOOKUP(K37, 'Duke 3'!$A$3:$B998,2, 0), 0) -> 0 | P37: =IFERROR(VLOOKUP(K37, 'Duke 4'!$A$3:$B998,2, 0), 0) -> 960 | Q37: =IFERROR(VLOOKUP(K37, Proof!$A$3:B998,2, 0), 0) -> 145.45455
A38: =ROW()-1 -> 37 | B38: 2028dhe | C38: =0.35*LARGE(D38:G38,1)+0.35*LARGE(D38:G38,2)+0.2*LARGE(D38:G38,3)+0.1*H38 -> 875.54545 | D38: =IFERROR(VLOOKUP(B38, 'Duke 1'!A$3:$B$85,2, 0), 0) -> 0 | E38: =IFERROR(VLOOKUP(B38, 'Duke 2'!A$3:$B$522,2, 0), 0) -> 1500 | F38: =IFERROR(VLOOKUP(B38, 'Duke 3'!A$3:$B998,2, 0), 0) -> 0 | G38: =IFERROR(VLOOKUP(B38, 'Duke 4'!A$3:$B998,2, 0), 0) -> 960 | H38: =IFERROR(VLOOKUP(B38, Proof!A$2:$B998,2, 0), 0) -> 145.45455 | K38: 2029achennad | L38: =0.3*LARGE(M38:P38,1)+0.3*LARGE(M38:P38,2)+0.2*LARGE(M38:P38,3)+0.2*Q38 -> 767.09091 | M38: =IFERROR(VLOOKUP(K38, 'Duke 1'!$A$3:$B998,2, 0), 0) -> 0 | N38: =IFERROR(VLOOKUP(K38, 'Duke 2'!$A$3:$B998,2, 0), 0) -> 1500 | O38: =IFERROR(VLOOKUP(K38, 'Duke 3'!$A$3:$B998,2, 0), 0) -> 0 | P38: =IFERROR(VLOOKUP(K38, 'Duke 4'!$A$3:$B998,2, 0), 0) -> 960 | Q38: =IFERROR(VLOOKUP(K38, Proof!$A$3:B998,2, 0), 0) -> 145.45455
A39: =ROW()-1 -> 38 | B39: 2029yahn | C39: =0.35*LARGE(D39:G39,1)+0.35*LARGE(D39:G39,2)+0.2*LARGE(D39:G39,3)+0.1*H39 -> 861 | D39: =IFERROR(VLOOKUP(B39, 'Duke 1'!A$3:$B$85,2, 0), 0) -> 0 | E39: =IFERROR(VLOOKUP(B39, 'Duke 2'!A$3:$B$522,2, 0), 0) -> 1500 | F39: =IFERROR(VLOOKUP(B39, 'Duke 3'!A$3:$B998,2, 0), 0) -> 0 | G39: =IFERROR(VLOOKUP(B39, 'Duke 4'!A$3:$B998,2, 0), 0) -> 960 | H39: =IFERROR(VLOOKUP(B39, Proof!A$2:$B998,2, 0), 0) -> 0 | K39: 2028dhe | L39: =0.3*LARGE(M39:P39,1)+0.3*LARGE(M39:P39,2)+0.2*LARGE(M39:P39,3)+0.2*Q39 -> 767.09091 | M39: =IFERROR(VLOOKUP(K39, 'Duke 1'!$A$3:$B998,2, 0), 0) -> 0 | N39: =IFERROR(VLOOKUP(K39, 'Duke 2'!$A$3:$B998,2, 0), 0) -> 1500 | O39: =IFERROR(VLOOKUP(K39, 'Duke 3'!$A$3:$B998,2, 0), 0) -> 0 | P39: =IFERROR(VLOOKUP(K39, 'Duke 4'!$A$3:$B998,2, 0), 0) -> 960 | Q39: =IFERROR(VLOOKUP(K39, Proof!$A$3:B998,2, 0), 0) -> 145.45455
A40: =ROW()-1 -> 39 | B40: 2029amahapat | C40: =0.35*LARGE(D40:G40,1)+0.35*LARGE(D40:G40,2)+0.2*LARGE(D40:G40,3)+0.1*H40 -> 861 | D40: =IFERROR(VLOOKUP(B40, 'Duke 1'!A$3:$B$85,2, 0), 0) -> 0 | E40: =IFERROR(VLOOKUP(B40, 'Duke 2'!A$3:$B$522,2, 0), 0) -> 1500 | F40: =IFERROR(VLOOKUP(B40, 'Duke 3'!A$3:$B998,2, 0), 0) -> 0 | G40: =IFERROR(VLOOKUP(B40, 'Duke 4'!A$3:$B998,2, 0), 0) -> 960 | H40: =IFERROR(VLOOKUP(B40, Proof!A$2:$B998,2, 0), 0) -> 0 | K40: 2029bwang | L40: =0.3*LARGE(M40:P40,1)+0.3*LARGE(M40:P40,2)+0.2*LARGE(M40:P40,3)+0.2*Q40 -> 745.75758 | M40: =IFERROR(VLOOKUP(K40, 'Duke 1'!$A$3:$B998,2, 0), 0) -> 0 | N40: =IFERROR(VLOOKUP(K40, 'Duke 2'!$A$3:$B998,2, 0), 0) -> 1500 | O40: =IFERROR(VLOOKUP(K40, 'Duke 3'!$A$3:$B998,2, 0), 0) -> 888.88889 | P40: =IFERROR(VLOOKUP(K40, 'Duke 4'!$A$3:$B998,2, 0), 0) -> 0 | Q40: =IFERROR(VLOOKUP(K40, Proof!$A$3:B998,2, 0), 0) -> 145.45455
...

Sheet Duke 1
A1: Ion ID | B1: Index | C1: userId | D1: Total | E1: P1 | F1: P2 | G1: P3 | H1: P4 | I1: P5 | J1: P6 | L1: Top 12 Average | M1: {=sum(large(D3:D556,column(indirect("$A$1:" &ADDRESS( 1, 12)))))/12} -> 3.1666667
A2: SUMS | E2: =SUM(E3:E104) -> 21 | F2: =SUM(F3:F104) -> 5 | G2: =SUM(G3:G104) -> 15 | H2: =SUM(H3:H104) -> 7 | I2: =SUM(I3:I104) -> 5 | J2: =SUM(J3:J104) -> 5
A3: 2028syan | B3: =D3/M$1*2000 -> 3789.4737 | C3: =VLOOKUP(A3, hash!A$2:B$500, 2, 0) -> 66e1e1237a8e6dc2aed3a642 | D3: =SUM(E3:J3) -> 6 | E3: 1 | F3: 1 | G3: 1 | H3: 1 | I3: 1 | J3: 1
A4: 2026rwang | B4: =D4/M$1*2000 -> 3157.8947 | C4: =VLOOKUP(A4, hash!A$2:B$500, 2, 0) -> 6322202c0aa8ba2dbc57c0a6 | D4: =SUM(E4:J4) -> 5 | E4: 1 | F4: 1 | G4: 1 | H4: 1 | I4: 0 | J4: 1
A5: 2027pdu | B5: =D5/M$1*2000 -> 3157.8947 | C5: =VLOOKUP(A5, hash!A$2:B$500, 2, 0) -> 6502005e1d8cbbbd315ad52c | D5: =SUM(E5:J5) -> 5 | E5: 1 | F5: 1 | G5: 0 | H5: 1 | I5: 1 | J5: 1
A6: 2027esombhat | B6: =D6/M$1*2000 -> 2526.3158 | C6: =VLOOKUP(A6, hash!A$2:B$500, 2, 0) -> 65020037540ba7cc68909a9b | D6: =SUM(E6:J6) -> 4 | E6: 1 | F6: 0 | G6: 1 | H6: 1 | I6: 1 | J6: 0
A7: 2026jma | B7: =D7/M$1*2000 -> 2526.3158 | C7: =VLOOKUP(A7, hash!A$2:B$500, 2, 0) -> 65020be78f2b101294bb3da8 | D7: =SUM(E7:J7) -> 4 | E7: 1 | F7: 1 | G7: 1 | H7: 1 | I7: 0 | J7: 0
A8: 2027vcao | B8: =D8/M$1*2000 -> 1894.7368 | C8: =VLOOKUP(A8, hash!A$2:B$500, 2, 0) -> 65020bfc097ac3c9d063264d | D8: =SUM(E8:J8) -> 3 | E8: 1 | F8: 0 | G8: 1 | H8: 0 | I8: 0 | J8: 1
A9: 2026mzhao | B9: =D9/M$1*2000 -> 1263.1579 | C9: =VLOOKUP(A9, hash!A$2:B$500, 2, 0) -> 632220270aa8ba2dbc57c0a4 | D9: =SUM(E9:J9) -> 2 | E9: 1 | F9: 0 | G9: 1 | H9: 0 | I9: 0 | J9: 0
A10: 2027ahao | B10: =D10/M$1*2000 -> 1263.1579 | C10: =VLOOKUP(A10, hash!A$2:B$500, 2, 0) -> 6502003d1d8cbbbd315ad525 | D10: =SUM(E10:J10) -> 2 | E10: 1 | F10: 0 | G10: 0 | H10: 0 | I10: 1 | J10: 0
A11: 2027itennyso | B11: =D11/M$1*2000 -> 1263.1579 | C11: =VLOOKUP(A11, hash!A$2:B$500, 2, 0) -> 6502007357ae167867eac223 | D11: =SUM(E11:J11) -> 2 | E11: 1 | F11: 0 | G11: 1 | H11: 0 | I11: 0 | J11: 0
A12: 2027eshan | B12: =D12/M$1*2000 -> 1263.1579 | C12: =VLOOKUP(A12, hash!A$2:B$500, 2, 0) -> 66e1e1659bdd593ffcd624e6 | D12: =SUM(E12:J12) -> 2 | E12: 1 | F12: 0 | G12: 0 | H12: 1 | I12: 0 | J12: 0
A13: 2029sbi | B13: =D13/M$1*2000 -> 1263.1579 | C13: =VLOOKUP(A13, hash!A$2:B$500, 2, 0) -> 68c1d00f9147fa44206d10b5 | D13: =SUM(E13:J13) -> 2 | E13: 1 | F13: 0 | G13: 1 | H13: 0 | I13: 0 | J13: 0
A14: 2027eguo | B14: =D14/M$1*2000 -> 631.57895 | C14: =VLOOKUP(A14, hash!A$2:B$500, 2, 0) -> 66e1e1277a8e6dc2aed3a645 | D14: =SUM(E14:J14) -> 1 | E14: 0 | F14: 0 | G14: 0 | H14: 0 | I14: 0 | J14: 1
... A85: 2029bchu | B85: =D85/M$1*2000 -> 0 | C85: =VLOOKUP(A85, hash!A$2:B$500, 2, 0) -> #N/A | D85: =SUM(E85:J85) -> 0 | E85: 0 | F85: 0 | G85: 0 | H85: 0 | I85: 0 | J85: 0
B86: =D86/M$1*2000 -> 0 | C86: =VLOOKUP(A86, hash!A$2:B$500, 2, 0) -> #N/A | D86: =SUM(E86:J86) -> 0 | E86: 0 | F86: 0
B87: =D87/M$1*2000 -> 0 | C87: =VLOOKUP(A87, hash!A$2:B$500, 2, 0) -> #N/A | D87: =SUM(E87:J87) -> 0
B88: =D88/M$1*2000 -> 0 | C88: =VLOOKUP(A88, hash!A$2:B$500, 2, 0) -> #N/A | D88: =SUM(E88:J88) -> 0
B89: =D89/M$1*2000 -> 0 | C89: =VLOOKUP(A89, hash!A$2:B$500, 2, 0) -> #N/A | D89: =SUM(E89:J89) -> 0
B90: =D90/M$1*2000 -> 0 | C90: =VLOOKUP(A90, hash!A$2:B$500, 2, 0) -> #N/A | D90: =SUM(E90:J90) -> 0
B91: =D91/M$1*2000 -> 0 | C91: =VLOOKUP(A91, hash!A$2:B$500, 2, 0) -> #N/A | D91: =SUM(E91:J91) -> 0
B92: =D92/M$1*2000 -> 0 | C92: =VLOOKUP(A92, hash!A$2:B$500, 2, 0) -> #N/A | D92: =SUM(E92:J92) -> 0
B93: =D93/M$1*2000 -> 0 | C93: =VLOOKUP(A93, hash!A$2:B$500, 2, 0) -> #N/A | D93: =SUM(E93:J93) -> 0
B94: =D94/M$1*2000 -> 0 | C94: =VLOOKUP(A94, hash!A$2:B$500, 2, 0) -> #N/A | D94: =SUM(E94:J94) -> 0
B95: =D95/M$1*2000 -> 0 | C95: =VLOOKUP(A95, hash!A$2:B$500, 2, 0) -> #N/A | D95: =SUM(E95:J95) -> 0
B96: =D96/M$1*2000 -> 0 | C96: =VLOOKUP(A96, hash!A$2:B$500, 2, 0) -> #N/A | D96: =SUM(E96:J96) -> 0
B97: =D97/M$1*2000 -> 0 | C97: =VLOOKUP(A97, hash!A$2:B$500, 2, 0) -> #N/A | D97: =SUM(E97:J97) -> 0
B98: =D98/M$1*2000 -> 0 | C98: =VLOOKUP(A98, hash!A$2:B$500, 2, 0) -> #N/A | D98: =SUM(E98:J98) -> 0
... B104: =D104/M$1*2000 -> 0 | C104: =VLOOKUP(A104, hash!A$2:B$500, 2, 0) -> #N/A | D104: =SUM(E104:J104) -> 0

Sheet Duke 2
A1: Ion ID | B1: =D1/M$1*2000 -> 0 | C1: =VLOOKUP(A1, hash!A$2:B$500, 2, 0) -> #N/A | D1: =SUM(E1:J1) -> 0 | E1: P1 | F1: P2 | G1: P3 | H1: P4 | I1: P5 | J1: P6 | L1: Top 12 Average | M1: {=sum(large(D3:D993,column(indirect("$A$1:" &ADDRESS( 1, 12)))))/12} -> 1.3333333
E2: =SUM(E3:E547) -> 0 | F2: =SUM(F3:F547) -> 3 | G2: =SUM(G3:G547) -> 2 | H2: =SUM(H3:H547) -> 0 | I2: =SUM(I3:I547) -> 1 | J2: =SUM(J3:J547) -> 74
A3: 2026rwang | B3: =D3/M$1*2000 -> 6000 | C3: =VLOOKUP(A3, hash!A$2:B$500, 2, 0) -> 6322202c0aa8ba2dbc57c0a6 | D3: =SUM(E3:J3) -> 4 | E3: 0 | F3: 1 | G3: 1 | H3: 0 | I3: 1 | J3: 1
A4: 2029nmaloney | B4: =D4/M$1*2000 -> 3000 | C4: =VLOOKUP(A4, hash!A$2:B$500, 2, 0) -> 68c1ceeed4e889598e7f612e | D4: =SUM(E4:J4) -> 2 | E4: 0 | F4: 0 | G4: 1 | H4: 0 | I4: 0 | J4: 1
A5: 2026mzhao | B5: =D5/M$1*2000 -> 1500 | C5: =VLOOKUP(A5, hash!A$2:B$500, 2, 0) -> 632220270aa8ba2dbc57c0a4 | D5: =SUM(E5:J5) -> 1 | E5: 0 | F5: 0 | G5: 0 | H5: 0 | I5: 0 | J5: 1
A6: 2026owu | B6: =D6/M$1*2000 -> 1500 | C6: =VLOOKUP(A6, hash!A$2:B$500, 2, 0) -> 6322236ef382c17890e6a3e1 | D6: =SUM(E6:J6) -> 1 | E6: 0 | F6: 0 | G6: 0 | H6: 0 | I6: 0 | J6: 1
A7: 2026cmorimot | B7: =D7/M$1*2000 -> 1500 | C7: =VLOOKUP(A7, hash!A$2:B$500, 2, 0) -> 63222c2fed58d92b843f7cbf | D7: =SUM(E7:J7) -> 1 | E7: 0 | F7: 0 | G7: 0 | H7: 0 | I7: 0 | J7: 1
A8: 2026rsingh2 | B8: =D8/M$1*2000 -> 1500 | C8: =VLOOKUP(A8, hash!A$2:B$500, 2, 0) -> 63222da0116f680d68804fa7 | D8: =SUM(E8:J8) -> 1 | E8: 0 | F8: 0 | G8: 0 | H8: 0 | I8: 0 | J8: 1
A9: 2026agupta | B9: =D9/M$1*2000 -> 1500 | C9: =VLOOKUP(A9, hash!A$2:B$500, 2, 0) -> 6334931c5db42318c75b941a | D9: =SUM(E9:J9) -> 1 | E9: 0 | F9: 0 | G9: 0 | H9: 0 | I9: 0 | J9: 1
A10: 2026abaradhi | B10: =D10/M$1*2000 -> 1500 | C10: =VLOOKUP(A10, hash!A$2:B$500, 2, 0) -> 64515f804c53122bd367c958 | D10: =SUM(E10:J10) -> 1 | E10: 0 | F10: 0 | G10: 0 | H10: 0 | I10: 0 | J10: 1
A11: 2027esombhat | B11: =D11/M$1*2000 -> 1500 | C11: =VLOOKUP(A11, hash!A$2:B$500, 2, 0) -> 65020037540ba7cc68909a9b | D11: =SUM(E11:J11) -> 1 | E11: 0 | F11: 0 | G11: 0 | H11: 0 | I11: 0 | J11: 1
A12: 2027ahao | B12: =D12/M$1*2000 -> 1500 | C12: =VLOOKUP(A12, hash!A$2:B$500, 2, 0) -> 6502003d1d8cbbbd315ad525 | D12: =SUM(E12:J12) -> 1 | E12: 0 | F12: 0 | G12: 0 | H12: 0 | I12: 0 | J12: 1
A13: 2027pdu | B13: =D13/M$1*2000 -> 1500 | C13: =VLOOKUP(A13, hash!A$2:B$500, 2, 0) -> 6502005e1d8cbbbd315ad52c | D13: =SUM(E13:J13) -> 1 | E13: 0 | F13: 0 | G13: 0 | H13: 0 | I13: 0 | J13: 1
A14: 2027itennyso | B14: =D14/M$1*2000 -> 1500 | C14: =VLOOKUP(A14, hash!A$2:B$500, 2, 0) -> 6502007357ae167867eac223 | D14: =SUM(E14:J14) -> 1 | E14: 0 | F14: 0 | G14: 0 | H14: 0 | I14: 0 | J14: 1
... A489: 2029azhang | B489: =D489/M$1*2000 -> 0 | C489: =VLOOKUP(A489, hash!A$2:B$500, 2, 0) -> 68c1c4b68d697869a6c944dd | D489: =SUM(E489:J489) -> 0 | E489: 0 | F489: 0 | G489: 0 | H489: 0 | I489: 0 | J489: 0
A490: 2029jshah1 | B490: =D490/M$1*2000 -> 0 | C490: =VLOOKUP(A490, hash!A$2:B$500, 2, 0) -> 68c1c4be8d697869a6c944e0 | D490: =SUM(E490:J490) -> 0 | E490: =SUM(E23:E489) -> 0 | F490: 0 | G490: 0 | H490: 0 | I490: 0 | J490: 0
A491: 2028dpark | B491: =D491/M$1*2000 -> 0 | C491: =VLOOKUP(A491, hash!A$2:B$500, 2, 0) -> 68c1cdeef8ef417ee79a4d67 | D491: =SUM(E491:J491) -> 0 | E491: 0 | F491: 0 | G491: 0 | H491: 0 | I491: 0 | J491: 0
A492: 2029aliu | B492: =D492/M$1*2000 -> 0 | C492: =VLOOKUP(A492, hash!A$2:B$500, 2, 0) -> 68c1ce28f8ef417ee79a4d6d | D492: =SUM(E492:J492) -> 0 | E492: 0 | F492: 0 | G492: 0 | H492: 0 | I492: 0 | J492: 0
